Workbook

Sheet Assumptions
A1: Case Pack Assumptions
A2: Container Size | B2: Units per Case
A3: Gallon | B3: 4
A4: Half Gallon | B4: 9
A5: Quart | B5: 9
A6: Pint | B6: 20
A7: Other / unspecified | B7: 1
A9: Rule: item numbers ending in "P" are partial-case sales — quantity is already in units, so pack = 1. All other item numbers are whole cases and are multiplied by the pack size above.

Sheet Product Summary
A1: Item Number | B1: Description | C1: Container Size | D1: Units per Case | E1: Whole Cases Sold | F1: Units from Whole Cases | G1: Partial-Case Units Sold | H1: Total Units Shipped | I1: % of Total Units | J1: Line Items
A2: 6002 | B2: 2% Milk Dispenser | C2: =IF(ISNUMBER(SEARCH("HALF GALLON",$B2)),"Half Gallon",IF(ISNUMBER(SEARCH("GALLON",$B2)),"Gallon",IF(ISNUMBER(SEARCH("QUART",$B2)),"Quart",IF(ISNUMBER(SEARCH("PINT",$B2)),"Pint","Other")))) -> Other | D2: =IFERROR(INDEX(Assumptions!$B$3:$B$7,MATCH($C2,Assumptions!$A$3:$A$7,0)),Assumptions!$B$7) -> 1 | E2: =SUMIF('Raw Data'!$B$2:$B$878,$A2,'Raw Data'!$E$2:$E$878) -> 148 | F2: =$E2*$D2 -> 148 | G2: =SUMIF('Raw Data'!$B$2:$B$878,$A2&"P",'Raw Data'!$E$2:$E$878) -> 0 | H2: =$F2+$G2 -> 148 | I2: =$H2/$H$24 -> 0.00079451143 | J2: =COUNTIF('Raw Data'!$B$2:$B$878,$A2)+COUNTIF('Raw Data'!$B$2:$B$878,$A2&"P") -> 47
A3: 6005 | B3: Whole Milk Gallon | C3: =IF(ISNUMBER(SEARCH("HALF GALLON",$B3)),"Half Gallon",IF(ISNUMBER(SEARCH("GALLON",$B3)),"Gallon",IF(ISNUMBER(SEARCH("QUART",$B3)),"Quart",IF(ISNUMBER(SEARCH("PINT",$B3)),"Pint","Other")))) -> Gallon | D3: =IFERROR(INDEX(Assumptions!$B$3:$B$7,MATCH($C3,Assumptions!$A$3:$A$7,0)),Assumptions!$B$7) -> 4 | E3: =SUMIF('Raw Data'!$B$2:$B$878,$A3,'Raw Data'!$E$2:$E$878) -> 1016 | F3: =$E3*$D3 -> 4064 | G3: =SUMIF('Raw Data'!$B$2:$B$878,$A3&"P",'Raw Data'!$E$2:$E$878) -> 1257 | H3: =$F3+$G3 -> 5321 | I3: =$H3/$H$24 -> 0.028564833 | J3: =COUNTIF('Raw Data'!$B$2:$B$878,$A3)+COUNTIF('Raw Data'!$B$2:$B$878,$A3&"P") -> 101
A4: 6006 | B4: 2% Reduced Fat Milk Gallon | C4: =IF(ISNUMBER(SEARCH("HALF GALLON",$B4)),"Half Gallon",IF(ISNUMBER(SEARCH("GALLON",$B4)),"Gallon",IF(ISNUMBER(SEARCH("QUART",$B4)),"Quart",IF(ISNUMBER(SEARCH("PINT",$B4)),"Pint","Other")))) -> Gallon | D4: =IFERROR(INDEX(Assumptions!$B$3:$B$7,MATCH($C4,Assumptions!$A$3:$A$7,0)),Assumptions!$B$7) -> 4 | E4: =SUMIF('Raw Data'!$B$2:$B$878,$A4,'Raw Data'!$E$2:$E$878) -> 671 | F4: =$E4*$D4 -> 2684 | G4: =SUMIF('Raw Data'!$B$2:$B$878,$A4&"P",'Raw Data'!$E$2:$E$878) -> 959 | H4: =$F4+$G4 -> 3643 | I4: =$H4/$H$24 -> 0.019556791 | J4: =COUNTIF('Raw Data'!$B$2:$B$878,$A4)+COUNTIF('Raw Data'!$B$2:$B$878,$A4&"P") -> 58
A5: 6010 | B5: Fat Free (Skim) Milk Gallon | C5: =IF(ISNUMBER(SEARCH("HALF GALLON",$B5)),"Half Gallon",IF(ISNUMBER(SEARCH("GALLON",$B5)),"Gallon",IF(ISNUMBER(SEARCH("QUART",$B5)),"Quart",IF(ISNUMBER(SEARCH("PINT",$B5)),"Pint","Other")))) -> Gallon | D5: =IFERROR(INDEX(Assumptions!$B$3:$B$7,MATCH($C5,Assumptions!$A$3:$A$7,0)),Assumptions!$B$7) -> 4 | E5: =SUMIF('Raw Data'!$B$2:$B$878,$A5,'Raw Data'!$E$2:$E$878) -> 48 | F5: =$E5*$D5 -> 192 | G5: =SUMIF('Raw Data'!$B$2:$B$878,$A5&"P",'Raw Data'!$E$2:$E$878) -> 102 | H5: =$F5+$G5 -> 294 | I5: =$H5/$H$24 -> 0.0015782862 | J5: =COUNTIF('Raw Data'!$B$2:$B$878,$A5)+COUNTIF('Raw Data'!$B$2:$B$878,$A5&"P") -> 6
A6: 6011 | B6: 1% Low Fat Milk Gallon | C6: =IF(ISNUMBER(SEARCH("HALF GALLON",$B6)),"Half Gallon",IF(ISNUMBER(SEARCH("GALLON",$B6)),"Gallon",IF(ISNUMBER(SEARCH("QUART",$B6)),"Quart",IF(ISNUMBER(SEARCH("PINT",$B6)),"Pint","Other")))) -> Gallon | D6: =IFERROR(INDEX(Assumptions!$B$3:$B$7,MATCH($C6,Assumptions!$A$3:$A$7,0)),Assumptions!$B$7) -> 4 | E6: =SUMIF('Raw Data'!$B$2:$B$878,$A6,'Raw Data'!$E$2:$E$878) -> 75 | F6: =$E6*$D6 -> 300 | G6: =SUMIF('Raw Data'!$B$2:$B$878,$A6&"P",'Raw Data'!$E$2:$E$878) -> 18 | H6: =$F6+$G6 -> 318 | I6: =$H6/$H$24 -> 0.0017071259 | J6: =COUNTIF('Raw Data'!$B$2:$B$878,$A6)+COUNTIF('Raw Data'!$B$2:$B$878,$A6&"P") -> 5
A7: 6012 | B7: Chocolate Whole Milk Gallon | C7: =IF(ISNUMBER(SEARCH("HALF GALLON",$B7)),"Half Gallon",IF(ISNUMBER(SEARCH("GALLON",$B7)),"Gallon",IF(ISNUMBER(SEARCH("QUART",$B7)),"Quart",IF(ISNUMBER(SEARCH("PINT",$B7)),"Pint","Other")))) -> Gallon | D7: =IFERROR(INDEX(Assumptions!$B$3:$B$7,MATCH($C7,Assumptions!$A$3:$A$7,0)),Assumptions!$B$7) -> 4 | E7: =SUMIF('Raw Data'!$B$2:$B$878,$A7,'Raw Data'!$E$2:$E$878) -> 57 | F7: =$E7*$D7 -> 228 | G7: =SUMIF('Raw Data'!$B$2:$B$878,$A7&"P",'Raw Data'!$E$2:$E$878) -> 164 | H7: =$F7+$G7 -> 392 | I7: =$H7/$H$24 -> 0.0021043816 | J7: =COUNTIF('Raw Data'!$B$2:$B$878,$A7)+COUNTIF('Raw Data'!$B$2:$B$878,$A7&"P") -> 19
A8: 6013 | B8: Whole Milk - HALF GALLON | C8: =IF(ISNUMBER(SEARCH("HALF GALLON",$B8)),"Half Gallon",IF(ISNUMBER(SEARCH("GALLON",$B8)),"Gallon",IF(ISNUMBER(SEARCH("QUART",$B8)),"Quart",IF(ISNUMBER(SEARCH("PINT",$B8)),"Pint","Other")))) -> Half Gallon | D8: =IFERROR(INDEX(Assumptions!$B$3:$B$7,MATCH($C8,Assumptions!$A$3:$A$7,0)),Assumptions!$B$7) -> 9 | E8: =SUMIF('Raw Data'!$B$2:$B$878,$A8,'Raw Data'!$E$2:$E$878) -> 192 | F8: =$E8*$D8 -> 1728 | G8: =SUMIF('Raw Data'!$B$2:$B$878,$A8&"P",'Raw Data'!$E$2:$E$878) -> 1622 | H8: =$F8+$G8 -> 3350 | I8: =$H8/$H$24 -> 0.017983874 | J8: =COUNTIF('Raw Data'!$B$2:$B$878,$A8)+COUNTIF('Raw Data'!$B$2:$B$878,$A8&"P") -> 48
A9: 6014 | B9: 2% Milk - HALF GALLON | C9: =IF(ISNUMBER(SEARCH("HALF GALLON",$B9)),"Half Gallon",IF(ISNUMBER(SEARCH("GALLON",$B9)),"Gallon",IF(ISNUMBER(SEARCH("QUART",$B9)),"Quart",IF(ISNUMBER(SEARCH("PINT",$B9)),"Pint","Other")))) -> Half Gallon | D9: =IFERROR(INDEX(Assumptions!$B$3:$B$7,MATCH($C9,Assumptions!$A$3:$A$7,0)),Assumptions!$B$7) -> 9 | E9: =SUMIF('Raw Data'!$B$2:$B$878,$A9,'Raw Data'!$E$2:$E$878) -> 1202 | F9: =$E9*$D9 -> 10818 | G9: =SUMIF('Raw Data'!$B$2:$B$878,$A9&"P",'Raw Data'!$E$2:$E$878) -> 1519 | H9: =$F9+$G9 -> 12337 | I9: =$H9/$H$24 -> 0.06622897 | J9: =COUNTIF('Raw Data'!$B$2:$B$878,$A9)+COUNTIF('Raw Data'!$B$2:$B$878,$A9&"P") -> 66
A10: 6018 | B10: Skim No Fat Milk - HALF GALLON | C10: =IF(ISNUMBER(SEARCH("HALF GALLON",$B10)),"Half Gallon",IF(ISNUMBER(SEARCH("GALLON",$B10)),"Gallon",IF(ISNUMBER(SEARCH("QUART",$B10)),"Quart",IF(ISNUMBER(SEARCH("PINT",$B10)),"Pint","Other")))) -> Half Gallon | D10: =IFERROR(INDEX(Assumptions!$B$3:$B$7,MATCH($C10,Assumptions!$A$3:$A$7,0)),Assumptions!$B$7) -> 9 | E10: =SUMIF('Raw Data'!$B$2:$B$878,$A10,'Raw Data'!$E$2:$E$878) -> 32 | F10: =$E10*$D10 -> 288 | G10: =SUMIF('Raw Data'!$B$2:$B$878,$A10&"P",'Raw Data'!$E$2:$E$878) -> 96 | H10: =$F10+$G10 -> 384 | I10: =$H10/$H$24 -> 0.0020614351 | J10: =COUNTIF('Raw Data'!$B$2:$B$878,$A10)+COUNTIF('Raw Data'!$B$2:$B$878,$A10&"P") -> 14
A11: 6020 | B11: Chocolate Whole Milk - HALF GALLON | C11: =IF(ISNUMBER(SEARCH("HALF GALLON",$B11)),"Half Gallon",IF(ISNUMBER(SEARCH("GALLON",$B11)),"Gallon",IF(ISNUMBER(SEARCH("QUART",$B11)),"Quart",IF(ISNUMBER(SEARCH("PINT",$B11)),"Pint","Other")))) -> Half Gallon | D11: =IFERROR(INDEX(Assumptions!$B$3:$B$7,MATCH($C11,Assumptions!$A$3:$A$7,0)),Assumptions!$B$7) -> 9 | E11: =SUMIF('Raw Data'!$B$2:$B$878,$A11,'Raw Data'!$E$2:$E$878) -> 1031 | F11: =$E11*$D11 -> 9279 | G11: =SUMIF('Raw Data'!$B$2:$B$878,$A11&"P",'Raw Data'!$E$2:$E$878) -> 1627 | H11: =$F11+$G11 -> 10906 | I11: =$H11/$H$24 -> 0.058546903 | J11: =COUNTIF('Raw Data'!$B$2:$B$878,$A11)+COUNTIF('Raw Data'!$B$2:$B$878,$A11&"P") -> 52
A12: 6024 | B12: Whole Milk Quart | C12: =IF(ISNUMBER(SEARCH("HALF GALLON",$B12)),"Half Gallon",IF(ISNUMBER(SEARCH("GALLON",$B12)),"Gallon",IF(ISNUMBER(SEARCH("QUART",$B12)),"Quart",IF(ISNUMBER(SEARCH("PINT",$B12)),"Pint","Other")))) -> Quart | D12: =IFERROR(INDEX(Assumptions!$B$3:$B$7,MATCH($C12,Assumptions!$A$3:$A$7,0)),Assumptions!$B$7) -> 9 | E12: =SUMIF('Raw Data'!$B$2:$B$878,$A12,'Raw Data'!$E$2:$E$878) -> 14 | F12: =$E12*$D12 -> 126 | G12: =SUMIF('Raw Data'!$B$2:$B$878,$A12&"P",'Raw Data'!$E$2:$E$878) -> 549 | H12: =$F12+$G12 -> 675 | I12: =$H12/$H$24 -> 0.0036236163 | J12: =COUNTIF('Raw Data'!$B$2:$B$878,$A12)+COUNTIF('Raw Data'!$B$2:$B$878,$A12&"P") -> 18
A13: 6025 | B13: 2% Reduced Fat Milk Quart | C13: =IF(ISNUMBER(SEARCH("HALF GALLON",$B13)),"Half Gallon",IF(ISNUMBER(SEARCH("GALLON",$B13)),"Gallon",IF(ISNUMBER(SEARCH("QUART",$B13)),"Quart",IF(ISNUMBER(SEARCH("PINT",$B13)),"Pint","Other")))) -> Quart | D13: =IFERROR(INDEX(Assumptions!$B$3:$B$7,MATCH($C13,Assumptions!$A$3:$A$7,0)),Assumptions!$B$7) -> 9 | E13: =SUMIF('Raw Data'!$B$2:$B$878,$A13,'Raw Data'!$E$2:$E$878) -> 12 | F13: =$E13*$D13 -> 108 | G13: =SUMIF('Raw Data'!$B$2:$B$878,$A13&"P",'Raw Data'!$E$2:$E$878) -> 843 | H13: =$F13+$G13 -> 951 | I13: =$H13/$H$24 -> 0.0051052728 | J13: =COUNTIF('Raw Data'!$B$2:$B$878,$A13)+COUNTIF('Raw Data'!$B$2:$B$878,$A13&"P") -> 17
... A23: 7676 | B23: Village Pie Butter | C23: =IF(ISNUMBER(SEARCH("HALF GALLON",$B23)),"Half Gallon",IF(ISNUMBER(SEARCH("GALLON",$B23)),"Gallon",IF(ISNUMBER(SEARCH("QUART",$B23)),"Quart",IF(ISNUMBER(SEARCH("PINT",$B23)),"Pint","Other")))) -> Other | D23: =IFERROR(INDEX(Assumptions!$B$3:$B$7,MATCH($C23,Assumptions!$A$3:$A$7,0)),Assumptions!$B$7) -> 1 | E23: =SUMIF('Raw Data'!$B$2:$B$878,$A23,'Raw Data'!$E$2:$E$878) -> 20 | F23: =$E23*$D23 -> 20 | G23: =SUMIF('Raw Data'!$B$2:$B$878,$A23&"P",'Raw Data'!$E$2:$E$878) -> 0 | H23: =$F23+$G23 -> 20 | I23: =$H23/$H$24 -> 0.00010736641 | J23: =COUNTIF('Raw Data'!$B$2:$B$878,$A23)+COUNTIF('Raw Data'!$B$2:$B$878,$A23&"P") -> 20
A24: TOTAL | E24: =SUM(E2:E23) -> 11394 | F24: =SUM(F2:F23) -> 159670 | G24: =SUM(G2:G23) -> 26608 | H24: =SUM(H2:H23) -> 186278 | I24: =SUM(I2:I23) -> 1 | J24: =SUM(J2:J23) -> 877
A26: Whole cases (item numbers without a trailing "P") are multiplied by the case pack on the Assumptions tab. Item numbers ending in "P" are partial-case sales already stated in units.

Sheet ZIP Summary
A1: ZIP Code | B1: Total Units Shipped | C1: Line Items | D1: Distinct Ship-To #s | E1: Distance from Country Dairy (mi, straight-line)
A2: (Unspecified / Consolidated) | B2: =SUMIF('Raw Data'!$A$2:$A$878,$A2,'Raw Data'!$I$2:$I$878) -> 1830 | C2: =COUNTIF('Raw Data'!$A:$A,$A2) -> 83 | D2: =SUMPRODUCT((('Raw Data'!$A$2:$A$878=$A2)*1)/COUNTIFS('Raw Data'!$A$2:$A$878,'Raw Data'!$A$2:$A$878,'Raw Data'!$D$2:$D$878,'Raw Data'!$D$2:$D$878)) -> 6 | E2: =IFERROR(3958.8*ACOS(MIN(1,MAX(-1,SIN(RADIANS('ZIP Coordinates'!$C$2))*SIN(RADIANS(INDEX('ZIP Coordinates'!$C:$C,MATCH($A2,'ZIP Coordinates'!$A:$A,0))))+COS(RADIANS('ZIP Coordinates'!$C$2))*COS(RADIANS(INDEX('ZIP Coordinates'!$C:$C,MATCH($A2,'ZIP Coordinates'!$A:$A,0))))*COS(RADIANS(INDEX('ZIP Coordinates'!$D:$D,MATCH($A2,'ZIP Coordinates'!$A:$A,0))-'ZIP Coordinates'!$D$2))))),"N/A") -> N/A
A3: 43502 | B3: =SUMIF('Raw Data'!$A$2:$A$878,$A3,'Raw Data'!$I$2:$I$878) -> 4478 | C3: =COUNTIF('Raw Data'!$A:$A,$A3) -> 28 | D3: =SUMPRODUCT((('Raw Data'!$A$2:$A$878=$A3)*1)/COUNTIFS('Raw Data'!$A$2:$A$878,'Raw Data'!$A$2:$A$878,'Raw Data'!$D$2:$D$878,'Raw Data'!$D$2:$D$878)) -> 3 | E3: =IFERROR(3958.8*ACOS(MIN(1,MAX(-1,SIN(RADIANS('ZIP Coordinates'!$C$2))*SIN(RADIANS(INDEX('ZIP Coordinates'!$C:$C,MATCH($A3,'ZIP Coordinates'!$A:$A,0))))+COS(RADIANS('ZIP Coordinates'!$C$2))*COS(RADIANS(INDEX('ZIP Coordinates'!$C:$C,MATCH($A3,'ZIP Coordinates'!$A:$A,0))))*COS(RADIANS(INDEX('ZIP Coordinates'!$D:$D,MATCH($A3,'ZIP Coordinates'!$A:$A,0))-'ZIP Coordinates'!$D$2))))),"N/A") -> 174.08007
A4: 43506 | B4: =SUMIF('Raw Data'!$A$2:$A$878,$A4,'Raw Data'!$I$2:$I$878) -> 3746 | C4: =COUNTIF('Raw Data'!$A:$A,$A4) -> 25 | D4: =SUMPRODUCT((('Raw Data'!$A$2:$A$878=$A4)*1)/COUNTIFS('Raw Data'!$A$2:$A$878,'Raw Data'!$A$2:$A$878,'Raw Data'!$D$2:$D$878,'Raw Data'!$D$2:$D$878)) -> 3 | E4: =IFERROR(3958.8*ACOS(MIN(1,MAX(-1,SIN(RADIANS('ZIP Coordinates'!$C$2))*SIN(RADIANS(INDEX('ZIP Coordinates'!$C:$C,MATCH($A4,'ZIP Coordinates'!$A:$A,0))))+COS(RADIANS('ZIP Coordinates'!$C$2))*COS(RADIANS(INDEX('ZIP Coordinates'!$C:$C,MATCH($A4,'ZIP Coordinates'!$A:$A,0))))*COS(RADIANS(INDEX('ZIP Coordinates'!$D:$D,MATCH($A4,'ZIP Coordinates'!$A:$A,0))-'ZIP Coordinates'!$D$2))))),"N/A") -> 170.0067
A5: 43512 | B5: =SUMIF('Raw Data'!$A$2:$A$878,$A5,'Raw Data'!$I$2:$I$878) -> 105435 | C5: =COUNTIF('Raw Data'!$A:$A,$A5) -> 19 | D5: =SUMPRODUCT((('Raw Data'!$A$2:$A$878=$A5)*1)/COUNTIFS('Raw Data'!$A$2:$A$878,'Raw Data'!$A$2:$A$878,'Raw Data'!$D$2:$D$878,'Raw Data'!$D$2:$D$878)) -> 6 | E5: =IFERROR(3958.8*ACOS(MIN(1,MAX(-1,SIN(RADIANS('ZIP Coordinates'!$C$2))*SIN(RADIANS(INDEX('ZIP Coordinates'!$C:$C,MATCH($A5,'ZIP Coordinates'!$A:$A,0))))+COS(RADIANS('ZIP Coordinates'!$C$2))*COS(RADIANS(INDEX('ZIP Coordinates'!$C:$C,MATCH($A5,'ZIP Coordinates'!$A:$A,0))))*COS(RADIANS(INDEX('ZIP Coordinates'!$D:$D,MATCH($A5,'ZIP Coordinates'!$A:$A,0))-'ZIP Coordinates'!$D$2))))),"N/A") -> 186.92635
A6: 43517 | B6: =SUMIF('Raw Data'!$A$2:$A$878,$A6,'Raw Data'!$I$2:$I$878) -> 1351 | C6: =COUNTIF('Raw Data'!$A:$A,$A6) -> 19 | D6: =SUMPRODUCT((('Raw Data'!$A$2:$A$878=$A6)*1)/COUNTIFS('Raw Data'!$A$2:$A$878,'Raw Data'!$A$2:$A$878,'Raw Data'!$D$2:$D$878,'Raw Data'!$D$2:$D$878)) -> 1 | E6: =IFERROR(3958.8*ACOS(MIN(1,MAX(-1,SIN(RADIANS('ZIP Coordinates'!$C$2))*SIN(RADIANS(INDEX('ZIP Coordinates'!$C:$C,MATCH($A6,'ZIP Coordinates'!$A:$A,0))))+COS(RADIANS('ZIP Coordinates'!$C$2))*COS(RADIANS(INDEX('ZIP Coordinates'!$C:$C,MATCH($A6,'ZIP Coordinates'!$A:$A,0))))*COS(RADIANS(INDEX('ZIP Coordinates'!$D:$D,MATCH($A6,'ZIP Coordinates'!$A:$A,0))-'ZIP Coordinates'!$D$2))))),"N/A") -> 167.45112
A7: 43518 | B7: =SUMIF('Raw Data'!$A$2:$A$878,$A7,'Raw Data'!$I$2:$I$878) -> 1497 | C7: =COUNTIF('Raw Data'!$A:$A,$A7) -> 15 | D7: =SUMPRODUCT((('Raw Data'!$A$2:$A$878=$A7)*1)/COUNTIFS('Raw Data'!$A$2:$A$878,'Raw Data'!$A$2:$A$878,'Raw Data'!$D$2:$D$878,'Raw Data'!$D$2:$D$878)) -> 2 | E7: =IFERROR(3958.8*ACOS(MIN(1,MAX(-1,SIN(RADIANS('ZIP Coordinates'!$C$2))*SIN(RADIANS(INDEX('ZIP Coordinates'!$C:$C,MATCH($A7,'ZIP Coordinates'!$A:$A,0))))+COS(RADIANS('ZIP Coordinates'!$C$2))*COS(RADIANS(INDEX('ZIP Coordinates'!$C:$C,MATCH($A7,'ZIP Coordinates'!$A:$A,0))))*COS(RADIANS(INDEX('ZIP Coordinates'!$D:$D,MATCH($A7,'ZIP Coordinates'!$A:$A,0))-'ZIP Coordinates'!$D$2))))),"N/A") -> 158.36355
A8: 43521 | B8: =SUMIF('Raw Data'!$A$2:$A$878,$A8,'Raw Data'!$I$2:$I$878) -> 2739 | C8: =COUNTIF('Raw Data'!$A:$A,$A8) -> 26 | D8: =SUMPRODUCT((('Raw Data'!$A$2:$A$878=$A8)*1)/COUNTIFS('Raw Data'!$A$2:$A$878,'Raw Data'!$A$2:$A$878,'Raw Data'!$D$2:$D$878,'Raw Data'!$D$2:$D$878)) -> 3 | E8: =IFERROR(3958.8*ACOS(MIN(1,MAX(-1,SIN(RADIANS('ZIP Coordinates'!$C$2))*SIN(RADIANS(INDEX('ZIP Coordinates'!$C:$C,MATCH($A8,'ZIP Coordinates'!$A:$A,0))))+COS(RADIANS('ZIP Coordinates'!$C$2))*COS(RADIANS(INDEX('ZIP Coordinates'!$C:$C,MATCH($A8,'ZIP Coordinates'!$A:$A,0))))*COS(RADIANS(INDEX('ZIP Coordinates'!$D:$D,MATCH($A8,'ZIP Coordinates'!$A:$A,0))-'ZIP Coordinates'!$D$2))))),"N/A") -> 165.79391
A9: 43524 | B9: =SUMIF('Raw Data'!$A$2:$A$878,$A9,'Raw Data'!$I$2:$I$878) -> 1855 | C9: =COUNTIF('Raw Data'!$A:$A,$A9) -> 17 | D9: =SUMPRODUCT((('Raw Data'!$A$2:$A$878=$A9)*1)/COUNTIFS('Raw Data'!$A$2:$A$878,'Raw Data'!$A$2:$A$878,'Raw Data'!$D$2:$D$878,'Raw Data'!$D$2:$D$878)) -> 1 | E9: =IFERROR(3958.8*ACOS(MIN(1,MAX(-1,SIN(RADIANS('ZIP Coordinates'!$C$2))*SIN(RADIANS(INDEX('ZIP Coordinates'!$C:$C,MATCH($A9,'ZIP Coordinates'!$A:$A,0))))+COS(RADIANS('ZIP Coordinates'!$C$2))*COS(RADIANS(INDEX('ZIP Coordinates'!$C:$C,MATCH($A9,'ZIP Coordinates'!$A:$A,0))))*COS(RADIANS(INDEX('ZIP Coordinates'!$D:$D,MATCH($A9,'ZIP Coordinates'!$A:$A,0))-'ZIP Coordinates'!$D$2))))),"N/A") -> 199.33243
A10: 43526 | B10: =SUMIF('Raw Data'!$A$2:$A$878,$A10,'Raw Data'!$I$2:$I$878) -> 610 | C10: =COUNTIF('Raw Data'!$A:$A,$A10) -> 13 | D10: =SUMPRODUCT((('Raw Data'!$A$2:$A$878=$A10)*1)/COUNTIFS('Raw Data'!$A$2:$A$878,'Raw Data'!$A$2:$A$878,'Raw Data'!$D$2:$D$878,'Raw Data'!$D$2:$D$878)) -> 3 | E10: =IFERROR(3958.8*ACOS(MIN(1,MAX(-1,SIN(RADIANS('ZIP Coordinates'!$C$2))*SIN(RADIANS(INDEX('ZIP Coordinates'!$C:$C,MATCH($A10,'ZIP Coordinates'!$A:$A,0))))+COS(RADIANS('ZIP Coordinates'!$C$2))*COS(RADIANS(INDEX('ZIP Coordinates'!$C:$C,MATCH($A10,'ZIP Coordinates'!$A:$A,0))))*COS(RADIANS(INDEX('ZIP Coordinates'!$D:$D,MATCH($A10,'ZIP Coordinates'!$A:$A,0))-'ZIP Coordinates'!$D$2))))),"N/A") -> 175.36797
A11: 43528 | B11: =SUMIF('Raw Data'!$A$2:$A$878,$A11,'Raw Data'!$I$2:$I$878) -> 9 | C11: =COUNTIF('Raw Data'!$A:$A,$A11) -> 1 | D11: =SUMPRODUCT((('Raw Data'!$A$2:$A$878=$A11)*1)/COUNTIFS('Raw Data'!$A$2:$A$878,'Raw Data'!$A$2:$A$878,'Raw Data'!$D$2:$D$878,'Raw Data'!$D$2:$D$878)) -> 1 | E11: =IFERROR(3958.8*ACOS(MIN(1,MAX(-1,SIN(RADIANS('ZIP Coordinates'!$C$2))*SIN(RADIANS(INDEX('ZIP Coordinates'!$C:$C,MATCH($A11,'ZIP Coordinates'!$A:$A,0))))+COS(RADIANS('ZIP Coordinates'!$C$2))*COS(RADIANS(INDEX('ZIP Coordinates'!$C:$C,MATCH($A11,'ZIP Coordinates'!$A:$A,0))))*COS(RADIANS(INDEX('ZIP Coordinates'!$D:$D,MATCH($A11,'ZIP Coordinates'!$A:$A,0))-'ZIP Coordinates'!$D$2))))),"N/A") -> 188.62929
A12: 43532 | B12: =SUMIF('Raw Data'!$A$2:$A$878,$A12,'Raw Data'!$I$2:$I$878) -> 277 | C12: =COUNTIF('Raw Data'!$A:$A,$A12) -> 11 | D12: =SUMPRODUCT((('Raw Data'!$A$2:$A$878=$A12)*1)/COUNTIFS('Raw Data'!$A$2:$A$878,'Raw Data'!$A$2:$A$878,'Raw Data'!$D$2:$D$878,'Raw Data'!$D$2:$D$878)) -> 1 | E12: =IFERROR(3958.8*ACOS(MIN(1,MAX(-1,SIN(RADIANS('ZIP Coordinates'!$C$2))*SIN(RADIANS(INDEX('ZIP Coordinates'!$C:$C,MATCH($A12,'ZIP Coordinates'!$A:$A,0))))+COS(RADIANS('ZIP Coordinates'!$C$2))*COS(RADIANS(INDEX('ZIP Coordinates'!$C:$C,MATCH($A12,'ZIP Coordinates'!$A:$A,0))))*COS(RADIANS(INDEX('ZIP Coordinates'!$D:$D,MATCH($A12,'ZIP Coordinates'!$A:$A,0))-'ZIP Coordinates'!$D$2))))),"N/A") -> 188.59799
A13: 43533 | B13: =SUMIF('Raw Data'!$A$2:$A$878,$A13,'Raw Data'!$I$2:$I$878) -> 1683 | C13: =COUNTIF('Raw Data'!$A:$A,$A13) -> 76 | D13: =SUMPRODUCT((('Raw Data'!$A$2:$A$878=$A13)*1)/COUNTIFS('Raw Data'!$A$2:$A$878,'Raw Data'!$A$2:$A$878,'Raw Data'!$D$2:$D$878,'Raw Data'!$D$2:$D$878)) -> 2 | E13: =IFERROR(3958.8*ACOS(MIN(1,MAX(-1,SIN(RADIANS('ZIP Coordinates'!$C$2))*SIN(RADIANS(INDEX('ZIP Coordinates'!$C:$C,MATCH($A13,'ZIP Coordinates'!$A:$A,0))))+COS(RADIANS('ZIP Coordinates'!$C$2))*COS(RADIANS(INDEX('ZIP Coordinates'!$C:$C,MATCH($A13,'ZIP Coordinates'!$A:$A,0))))*COS(RADIANS(INDEX('ZIP Coordinates'!$D:$D,MATCH($A13,'ZIP Coordinates'!$A:$A,0))-'ZIP Coordinates'!$D$2))))),"N/A") -> 173.39844
... A81: 68138 | B81: =SUMIF('Raw Data'!$A$2:$A$878,$A81,'Raw Data'!$I$2:$I$878) -> 20 | C81: =COUNTIF('Raw Data'!$A:$A,$A81) -> 20 | D81: =SUMPRODUCT((('Raw Data'!$A$2:$A$878=$A81)*1)/COUNTIFS('Raw Data'!$A$2:$A$878,'Raw Data'!$A$2:$A$878,'Raw Data'!$D$2:$D$878,'Raw Data'!$D$2:$D$878)) -> 1 | E81: =IFERROR(3958.8*ACOS(MIN(1,MAX(-1,SIN(RADIANS('ZIP Coordinates'!$C$2))*SIN(RADIANS(INDEX('ZIP Coordinates'!$C:$C,MATCH($A81,'ZIP Coordinates'!$A:$A,0))))+COS(RADIANS('ZIP Coordinates'!$C$2))*COS(RADIANS(INDEX('ZIP Coordinates'!$C:$C,MATCH($A81,'ZIP Coordinates'!$A:$A,0))))*COS(RADIANS(INDEX('ZIP Coordinates'!$D:$D,MATCH($A81,'ZIP Coordinates'!$A:$A,0))-'ZIP Coordinates'!$D$2))))),"N/A") -> 526.42489
A82: GRAND TOTAL | B82: =SUMIF('Raw Data'!$A$2:$A$878,$A82,'Raw Data'!$I$2:$I$878) -> 0 | C82: =SUM(C2:C81) -> 877
B83: =SUMIF('Raw Data'!$A$2:$A$878,$A83,'Raw Data'!$I$2:$I$878) -> 0
A84: Note: 'Original PDF Subtotal' and grand total are copied from the source PDF (Kuster's Commodity Report, Covers Period Jun 01 2026 - Aug 19 2026) as a QC check against the recalculated totals in column B. Distance is straight-line ('as the crow flies') miles between ZIP code centroids, computed on the 'ZIP Coordinates' tab - see that tab for the data source and Country Dairy's origin ZIP.

Sheet Customer Summary
A1: Ship To (Customer) # | B1: ZIP Code | C1: Total Units Shipped | D1: Distance from Country Dairy (mi, straight-line) | E1: Notes
A2: 729815 | B2: 43512 | C2: =SUMIF('Raw Data'!$D$2:$D$878,$A2,'Raw Data'!$I$2:$I$878) -> 102577 | D2: =IFERROR(3958.8*ACOS(MIN(1,MAX(-1,SIN(RADIANS('ZIP Coordinates'!$C$2))*SIN(RADIANS(INDEX('ZIP Coordinates'!$C:$C,MATCH($B2,'ZIP Coordinates'!$A:$A,0))))+COS(RADIANS('ZIP Coordinates'!$C$2))*COS(RADIANS(INDEX('ZIP Coordinates'!$C:$C,MATCH($B2,'ZIP Coordinates'!$A:$A,0))))*COS(RADIANS(INDEX('ZIP Coordinates'!$D:$D,MATCH($B2,'ZIP Coordinates'!$A:$A,0))-'ZIP Coordinates'!$D$2))))),"N/A") -> 186.92635
A3: 2730 | B3: 43543 | C3: =SUMIF('Raw Data'!$D$2:$D$878,$A3,'Raw Data'!$I$2:$I$878) -> 2346 | D3: =IFERROR(3958.8*ACOS(MIN(1,MAX(-1,SIN(RADIANS('ZIP Coordinates'!$C$2))*SIN(RADIANS(INDEX('ZIP Coordinates'!$C:$C,MATCH($B3,'ZIP Coordinates'!$A:$A,0))))+COS(RADIANS('ZIP Coordinates'!$C$2))*COS(RADIANS(INDEX('ZIP Coordinates'!$C:$C,MATCH($B3,'ZIP Coordinates'!$A:$A,0))))*COS(RADIANS(INDEX('ZIP Coordinates'!$D:$D,MATCH($B3,'ZIP Coordinates'!$A:$A,0))-'ZIP Coordinates'!$D$2))))),"N/A") -> 161.3589
A4: 750094 | B4: 43570 | C4: =SUMIF('Raw Data'!$D$2:$D$878,$A4,'Raw Data'!$I$2:$I$878) -> 2138 | D4: =IFERROR(3958.8*ACOS(MIN(1,MAX(-1,SIN(RADIANS('ZIP Coordinates'!$C$2))*SIN(RADIANS(INDEX('ZIP Coordinates'!$C:$C,MATCH($B4,'ZIP Coordinates'!$A:$A,0))))+COS(RADIANS('ZIP Coordinates'!$C$2))*COS(RADIANS(INDEX('ZIP Coordinates'!$C:$C,MATCH($B4,'ZIP Coordinates'!$A:$A,0))))*COS(RADIANS(INDEX('ZIP Coordinates'!$D:$D,MATCH($B4,'ZIP Coordinates'!$A:$A,0))-'ZIP Coordinates'!$D$2))))),"N/A") -> 167.59264
A5: 2334 | B5: 46721 | C5: =SUMIF('Raw Data'!$D$2:$D$878,$A5,'Raw Data'!$I$2:$I$878) -> 1552 | D5: =IFERROR(3958.8*ACOS(MIN(1,MAX(-1,SIN(RADIANS('ZIP Coordinates'!$C$2))*SIN(RADIANS(INDEX('ZIP Coordinates'!$C:$C,MATCH($B5,'ZIP Coordinates'!$A:$A,0))))+COS(RADIANS('ZIP Coordinates'!$C$2))*COS(RADIANS(INDEX('ZIP Coordinates'!$C:$C,MATCH($B5,'ZIP Coordinates'!$A:$A,0))))*COS(RADIANS(INDEX('ZIP Coordinates'!$D:$D,MATCH($B5,'ZIP Coordinates'!$A:$A,0))-'ZIP Coordinates'!$D$2))))),"N/A") -> 164.84248
A6: 2276 | B6: 46803 | C6: =SUMIF('Raw Data'!$D$2:$D$878,$A6,'Raw Data'!$I$2:$I$878) -> 1370 | D6: =IFERROR(3958.8*ACOS(MIN(1,MAX(-1,SIN(RADIANS('ZIP Coordinates'!$C$2))*SIN(RADIANS(INDEX('ZIP Coordinates'!$C:$C,MATCH($B6,'ZIP Coordinates'!$A:$A,0))))+COS(RADIANS('ZIP Coordinates'!$C$2))*COS(RADIANS(INDEX('ZIP Coordinates'!$C:$C,MATCH($B6,'ZIP Coordinates'!$A:$A,0))))*COS(RADIANS(INDEX('ZIP Coordinates'!$D:$D,MATCH($B6,'ZIP Coordinates'!$A:$A,0))-'ZIP Coordinates'!$D$2))))),"N/A") -> 183.03433
A7: 750041 | B7: 43533 | C7: =SUMIF('Raw Data'!$D$2:$D$878,$A7,'Raw Data'!$I$2:$I$878) -> 1398 | D7: =IFERROR(3958.8*ACOS(MIN(1,MAX(-1,SIN(RADIANS('ZIP Coordinates'!$C$2))*SIN(RADIANS(INDEX('ZIP Coordinates'!$C:$C,MATCH($B7,'ZIP Coordinates'!$A:$A,0))))+COS(RADIANS('ZIP Coordinates'!$C$2))*COS(RADIANS(INDEX('ZIP Coordinates'!$C:$C,MATCH($B7,'ZIP Coordinates'!$A:$A,0))))*COS(RADIANS(INDEX('ZIP Coordinates'!$D:$D,MATCH($B7,'ZIP Coordinates'!$A:$A,0))-'ZIP Coordinates'!$D$2))))),"N/A") -> 173.39844
A8: 1632 | B8: 49274 | C8: =SUMIF('Raw Data'!$D$2:$D$878,$A8,'Raw Data'!$I$2:$I$878) -> 8830 | D8: =IFERROR(3958.8*ACOS(MIN(1,MAX(-1,SIN(RADIANS('ZIP Coordinates'!$C$2))*SIN(RADIANS(INDEX('ZIP Coordinates'!$C:$C,MATCH($B8,'ZIP Coordinates'!$A:$A,0))))+COS(RADIANS('ZIP Coordinates'!$C$2))*COS(RADIANS(INDEX('ZIP Coordinates'!$C:$C,MATCH($B8,'ZIP Coordinates'!$A:$A,0))))*COS(RADIANS(INDEX('ZIP Coordinates'!$D:$D,MATCH($B8,'ZIP Coordinates'!$A:$A,0))-'ZIP Coordinates'!$D$2))))),"N/A") -> 142.88958
A9: 750005 | B9: 43554 | C9: =SUMIF('Raw Data'!$D$2:$D$878,$A9,'Raw Data'!$I$2:$I$878) -> 2575 | D9: =IFERROR(3958.8*ACOS(MIN(1,MAX(-1,SIN(RADIANS('ZIP Coordinates'!$C$2))*SIN(RADIANS(INDEX('ZIP Coordinates'!$C:$C,MATCH($B9,'ZIP Coordinates'!$A:$A,0))))+COS(RADIANS('ZIP Coordinates'!$C$2))*COS(RADIANS(INDEX('ZIP Coordinates'!$C:$C,MATCH($B9,'ZIP Coordinates'!$A:$A,0))))*COS(RADIANS(INDEX('ZIP Coordinates'!$D:$D,MATCH($B9,'ZIP Coordinates'!$A:$A,0))-'ZIP Coordinates'!$D$2))))),"N/A") -> 159.71109
A10: 750086 | B10: 43506 | C10: =SUMIF('Raw Data'!$D$2:$D$878,$A10,'Raw Data'!$I$2:$I$878) -> 3149 | D10: =IFERROR(3958.8*ACOS(MIN(1,MAX(-1,SIN(RADIANS('ZIP Coordinates'!$C$2))*SIN(RADIANS(INDEX('ZIP Coordinates'!$C:$C,MATCH($B10,'ZIP Coordinates'!$A:$A,0))))+COS(RADIANS('ZIP Coordinates'!$C$2))*COS(RADIANS(INDEX('ZIP Coordinates'!$C:$C,MATCH($B10,'ZIP Coordinates'!$A:$A,0))))*COS(RADIANS(INDEX('ZIP Coordinates'!$D:$D,MATCH($B10,'ZIP Coordinates'!$A:$A,0))-'ZIP Coordinates'!$D$2))))),"N/A") -> 170.0067
A11: 750090 | B11: 43521 | C11: =SUMIF('Raw Data'!$D$2:$D$878,$A11,'Raw Data'!$I$2:$I$878) -> 1063 | D11: =IFERROR(3958.8*ACOS(MIN(1,MAX(-1,SIN(RADIANS('ZIP Coordinates'!$C$2))*SIN(RADIANS(INDEX('ZIP Coordinates'!$C:$C,MATCH($B11,'ZIP Coordinates'!$A:$A,0))))+COS(RADIANS('ZIP Coordinates'!$C$2))*COS(RADIANS(INDEX('ZIP Coordinates'!$C:$C,MATCH($B11,'ZIP Coordinates'!$A:$A,0))))*COS(RADIANS(INDEX('ZIP Coordinates'!$D:$D,MATCH($B11,'ZIP Coordinates'!$A:$A,0))-'ZIP Coordinates'!$D$2))))),"N/A") -> 165.79391
A12: 0251 | B12: (Unspecified / Consolidated) | C12: =SUMIF('Raw Data'!$D$2:$D$878,$A12,'Raw Data'!$I$2:$I$878) -> 872 | D12: =IFERROR(3958.8*ACOS(MIN(1,MAX(-1,SIN(RADIANS('ZIP Coordinates'!$C$2))*SIN(RADIANS(INDEX('ZIP Coordinates'!$C:$C,MATCH($B12,'ZIP Coordinates'!$A:$A,0))))+COS(RADIANS('ZIP Coordinates'!$C$2))*COS(RADIANS(INDEX('ZIP Coordinates'!$C:$C,MATCH($B12,'ZIP Coordinates'!$A:$A,0))))*COS(RADIANS(INDEX('ZIP Coordinates'!$D:$D,MATCH($B12,'ZIP Coordinates'!$A:$A,0))-'ZIP Coordinates'!$D$2))))),"N/A") -> N/A
A13: 0415 | B13: 49274 | C13: =SUMIF('Raw Data'!$D$2:$D$878,$A13,'Raw Data'!$I$2:$I$878) -> 7524 | D13: =IFERROR(3958.8*ACOS(MIN(1,MAX(-1,SIN(RADIANS('ZIP Coordinates'!$C$2))*SIN(RADIANS(INDEX('ZIP Coordinates'!$C:$C,MATCH($B13,'ZIP Coordinates'!$A:$A,0))))+COS(RADIANS('ZIP Coordinates'!$C$2))*COS(RADIANS(INDEX('ZIP Coordinates'!$C:$C,MATCH($B13,'ZIP Coordinates'!$A:$A,0))))*COS(RADIANS(INDEX('ZIP Coordinates'!$D:$D,MATCH($B13,'ZIP Coordinates'!$A:$A,0))-'ZIP Coordinates'!$D$2))))),"N/A") -> 142.88958
A14: 0898 | B14: 46737 | C14: =SUMIF('Raw Data'!$D$2:$D$878,$A14,'Raw Data'!$I$2:$I$878) -> 2891 | D14: =IFERROR(3958.8*ACOS(MIN(1,MAX(-1,SIN(RADIANS('ZIP Coordinates'!$C$2))*SIN(RADIANS(INDEX('ZIP Coordinates'!$C:$C,MATCH($B14,'ZIP Coordinates'!$A:$A,0))))+COS(RADIANS('ZIP Coordinates'!$C$2))*COS(RADIANS(INDEX('ZIP Coordinates'!$C:$C,MATCH($B14,'ZIP Coordinates'!$A:$A,0))))*COS(RADIANS(INDEX('ZIP Coordinates'!$D:$D,MATCH($B14,'ZIP Coordinates'!$A:$A,0))-'ZIP Coordinates'!$D$2))))),"N/A") -> 144.62059
A15: 0999 | B15: (Unspecified / Consolidated) | C15: =SUMIF('Raw Data'!$D$2:$D$878,$A15,'Raw Data'!$I$2:$I$878) -> 1337 | D15: =IFERROR(3958.8*ACOS(MIN(1,MAX(-1,SIN(RADIANS('ZIP Coordinates'!$C$2))*SIN(RADIANS(INDEX('ZIP Coordinates'!$C:$C,MATCH($B15,'ZIP Coordinates'!$A:$A,0))))+COS(RADIANS('ZIP Coordinates'!$C$2))*COS(RADIANS(INDEX('ZIP Coordinates'!$C:$C,MATCH($B15,'ZIP Coordinates'!$A:$A,0))))*COS(RADIANS(INDEX('ZIP Coordinates'!$D:$D,MATCH($B15,'ZIP Coordinates'!$A:$A,0))-'ZIP Coordinates'!$D$2))))),"N/A") -> N/A | E15: Ships to more than one ZIP in the source report (43526, 49232, (Unspecified / Consolidated)). ZIP shown is the one with the largest volume for this customer; distance is based on that ZIP only.
A16: 2338 | B16: 46703 | C16: =SUMIF('Raw Data'!$D$2:$D$878,$A16,'Raw Data'!$I$2:$I$878) -> 726 | D16: =IFERROR(3958.8*ACOS(MIN(1,MAX(-1,SIN(RADIANS('ZIP Coordinates'!$C$2))*SIN(RADIANS(INDEX('ZIP Coordinates'!$C:$C,MATCH($B16,'ZIP Coordinates'!$A:$A,0))))+COS(RADIANS('ZIP Coordinates'!$C$2))*COS(RADIANS(INDEX('ZIP Coordinates'!$C:$C,MATCH($B16,'ZIP Coordinates'!$A:$A,0))))*COS(RADIANS(INDEX('ZIP Coordinates'!$D:$D,MATCH($B16,'ZIP Coordinates'!$A:$A,0))-'ZIP Coordinates'!$D$2))))),"N/A") -> 147.51382
A17: 740086 | B17: 43557 | C17: =SUMIF('Raw Data'!$D$2:$D$878,$A17,'Raw Data'!$I$2:$I$878) -> 663 | D17: =IFERROR(3958.8*ACOS(MIN(1,MAX(-1,SIN(RADIANS('ZIP Coordinates'!$C$2))*SIN(RADIANS(INDEX('ZIP Coordinates'!$C:$C,MATCH($B17,'ZIP Coordinates'!$A:$A,0))))+COS(RADIANS('ZIP Coordinates'!$C$2))*COS(RADIANS(INDEX('ZIP Coordinates'!$C:$C,MATCH($B17,'ZIP Coordinates'!$A:$A,0))))*COS(RADIANS(INDEX('ZIP Coordinates'!$D:$D,MATCH($B17,'ZIP Coordinates'!$A:$A,0))-'ZIP Coordinates'!$D$2))))),"N/A") -> 173.66928
A18: 3054 | B18: 43524 | C18: =SUMIF('Raw Data'!$D$2:$D$878,$A18,'Raw Data'!$I$2:$I$878) -> 1855 | D18: =IFERROR(3958.8*ACOS(MIN(1,MAX(-1,SIN(RADIANS('ZIP Coordinates'!$C$2))*SIN(RADIANS(INDEX('ZIP Coordinates'!$C:$C,MATCH($B18,'ZIP Coordinates'!$A:$A,0))))+COS(RADIANS('ZIP Coordinates'!$C$2))*COS(RADIANS(INDEX('ZIP Coordinates'!$C:$C,MATCH($B18,'ZIP Coordinates'!$A:$A,0))))*COS(RADIANS(INDEX('ZIP Coordinates'!$D:$D,MATCH($B18,'ZIP Coordinates'!$A:$A,0))-'ZIP Coordinates'!$D$2))))),"N/A") -> 199.33243
A19: 750043 | B19: 43540 | C19: =SUMIF('Raw Data'!$D$2:$D$878,$A19,'Raw Data'!$I$2:$I$878) -> 876 | D19: =IFERROR(3958.8*ACOS(MIN(1,MAX(-1,SIN(RADIANS('ZIP Coordinates'!$C$2))*SIN(RADIANS(INDEX('ZIP Coordinates'!$C:$C,MATCH($B19,'ZIP Coordinates'!$A:$A,0))))+COS(RADIANS('ZIP Coordinates'!$C$2))*COS(RADIANS(INDEX('ZIP Coordinates'!$C:$C,MATCH($B19,'ZIP Coordinates'!$A:$A,0))))*COS(RADIANS(INDEX('ZIP Coordinates'!$D:$D,MATCH($B19,'ZIP Coordinates'!$A:$A,0))-'ZIP Coordinates'!$D$2))))),"N/A") -> 177.87377
A20: 750088 | B20: 43518 | C20: =SUMIF('Raw Data'!$D$2:$D$878,$A20,'Raw Data'!$I$2:$I$878) -> 1049 | D20: =IFERROR(3958.8*ACOS(MIN(1,MAX(-1,SIN(RADIANS('ZIP Coordinates'!$C$2))*SIN(RADIANS(INDEX('ZIP Coordinates'!$C:$C,MATCH($B20,'ZIP Coordinates'!$A:$A,0))))+COS(RADIANS('ZIP Coordinates'!$C$2))*COS(RADIANS(INDEX('ZIP Coordinates'!$C:$C,MATCH($B20,'ZIP Coordinates'!$A:$A,0))))*COS(RADIANS(INDEX('ZIP Coordinates'!$D:$D,MATCH($B20,'ZIP Coordinates'!$A:$A,0))-'ZIP Coordinates'!$D$2))))),"N/A") -> 158.36355
A21: 750084 | B21: 43557 | C21: =SUMIF('Raw Data'!$D$2:$D$878,$A21,'Raw Data'!$I$2:$I$878) -> 575 | D21: =IFERROR(3958.8*ACOS(MIN(1,MAX(-1,SIN(RADIANS('ZIP Coordinates'!$C$2))*SIN(RADIANS(INDEX('ZIP Coordinates'!$C:$C,MATCH($B21,'ZIP Coordinates'!$A:$A,0))))+COS(RADIANS('ZIP Coordinates'!$C$2))*COS(RADIANS(INDEX('ZIP Coordinates'!$C:$C,MATCH($B21,'ZIP Coordinates'!$A:$A,0))))*COS(RADIANS(INDEX('ZIP Coordinates'!$D:$D,MATCH($B21,'ZIP Coordinates'!$A:$A,0))-'ZIP Coordinates'!$D$2))))),"N/A") -> 173.66928
A22: 1264 | B22: 49540 | C22: =SUMIF('Raw Data'!$D$2:$D$878,$A22,'Raw Data'!$I$2:$I$878) -> 1157 | D22: =IFERROR(3958.8*ACOS(MIN(1,MAX(-1,SIN(RADIANS('ZIP Coordinates'!$C$2))*SIN(RADIANS(INDEX('ZIP Coordinates'!$C:$C,MATCH($B22,'ZIP Coordinates'!$A:$A,0))))+COS(RADIANS('ZIP Coordinates'!$C$2))*COS(RADIANS(INDEX('ZIP Coordinates'!$C:$C,MATCH($B22,'ZIP Coordinates'!$A:$A,0))))*COS(RADIANS(INDEX('ZIP Coordinates'!$D:$D,MATCH($B22,'ZIP Coordinates'!$A:$A,0))-'ZIP Coordinates'!$D$2))))),"N/A") -> N/A | E22: Ships to more than one ZIP in the source report (46540, 49540). ZIP shown is the one with the largest volume for this customer; distance is based on that ZIP only.
A23: 710052 | B23: 45831 | C23: =SUMIF('Raw Data'!$D$2:$D$878,$A23,'Raw Data'!$I$2:$I$878) -> 801 | D23: =IFERROR(3958.8*ACOS(MIN(1,MAX(-1,SIN(RADIANS('ZIP Coordinates'!$C$2))*SIN(RADIANS(INDEX('ZIP Coordinates'!$C:$C,MATCH($B23,'ZIP Coordinates'!$A:$A,0))))+COS(RADIANS('ZIP Coordinates'!$C$2))*COS(RADIANS(INDEX('ZIP Coordinates'!$C:$C,MATCH($B23,'ZIP Coordinates'!$A:$A,0))))*COS(RADIANS(INDEX('ZIP Coordinates'!$D:$D,MATCH($B23,'ZIP Coordinates'!$A:$A,0))-'ZIP Coordinates'!$D$2))))),"N/A") -> 200.09402
A24: 750096 | B24: 43502 | C24: =SUMIF('Raw Data'!$D$2:$D$878,$A24,'Raw Data'!$I$2:$I$878) -> 874 | D24: =IFERROR(3958.8*ACOS(MIN(1,MAX(-1,SIN(RADIANS('ZIP Coordinates'!$C$2))*SIN(RADIANS(INDEX('ZIP Coordinates'!$C:$C,MATCH($B24,'ZIP Coordinates'!$A:$A,0))))+COS(RADIANS('ZIP Coordinates'!$C$2))*COS(RADIANS(INDEX('ZIP Coordinates'!$C:$C,MATCH($B24,'ZIP Coordinates'!$A:$A,0))))*COS(RADIANS(INDEX('ZIP Coordinates'!$D:$D,MATCH($B24,'ZIP Coordinates'!$A:$A,0))-'ZIP Coordinates'!$D$2))))),"N/A") -> 174.08007
A25: 739026 | B25: 43545 | C25: =SUMIF('Raw Data'!$D$2:$D$878,$A25,'Raw Data'!$I$2:$I$878) -> 847 | D25: =IFERROR(3958.8*ACOS(MIN(1,MAX(-1,SIN(RADIANS('ZIP Coordinates'!$C$2))*SIN(RADIANS(INDEX('ZIP Coordinates'!$C:$C,MATCH($B25,'ZIP Coordinates'!$A:$A,0))))+COS(RADIANS('ZIP Coordinates'!$C$2))*COS(RADIANS(INDEX('ZIP Coordinates'!$C:$C,MATCH($B25,'ZIP Coordinates'!$A:$A,0))))*COS(RADIANS(INDEX('ZIP Coordinates'!$D:$D,MATCH($B25,'ZIP Coordinates'!$A:$A,0))-'ZIP Coordinates'!$D$2))))),"N/A") -> 186.95027
A26: 2844 | B26: 46746 | C26: =SUMIF('Raw Data'!$D$2:$D$878,$A26,'Raw Data'!$I$2:$I$878) -> 448 | D26: =IFERROR(3958.8*ACOS(MIN(1,MAX(-1,SIN(RADIANS('ZIP Coordinates'!$C$2))*SIN(RADIANS(INDEX('ZIP Coordinates'!$C:$C,MATCH($B26,'ZIP Coordinates'!$A:$A,0))))+COS(RADIANS('ZIP Coordinates'!$C$2))*COS(RADIANS(INDEX('ZIP Coordinates'!$C:$C,MATCH($B26,'ZIP Coordinates'!$A:$A,0))))*COS(RADIANS(INDEX('ZIP Coordinates'!$D:$D,MATCH($B26,'ZIP Coordinates'!$A:$A,0))-'ZIP Coordinates'!$D$2))))),"N/A") -> 133.78845
A27: 1678 | B27: 49288 | C27: =SUMIF('Raw Data'!$D$2:$D$878,$A27,'Raw Data'!$I$2:$I$878) -> 442 | D27: =IFERROR(3958.8*ACOS(MIN(1,MAX(-1,SIN(RADIANS('ZIP Coordinates'!$C$2))*SIN(RADIANS(INDEX('ZIP Coordinates'!$C:$C,MATCH($B27,'ZIP Coordinates'!$A:$A,0))))+COS(RADIANS('ZIP Coordinates'!$C$2))*COS(RADIANS(INDEX('ZIP Coordinates'!$C:$C,MATCH($B27,'ZIP Coordinates'!$A:$A,0))))*COS(RADIANS(INDEX('ZIP Coordinates'!$D:$D,MATCH($B27,'ZIP Coordinates'!$A:$A,0))-'ZIP Coordinates'!$D$2))))),"N/A") -> 158.22481
A28: 1486 | B28: 46514 | C28: =SUMIF('Raw Data'!$D$2:$D$878,$A28,'Raw Data'!$I$2:$I$878) -> 648 | D28: =IFERROR(3958.8*ACOS(MIN(1,MAX(-1,SIN(RADIANS('ZIP Coordinates'!$C$2))*SIN(RADIANS(INDEX('ZIP Coordinates'!$C:$C,MATCH($B28,'ZIP Coordinates'!$A:$A,0))))+COS(RADIANS('ZIP Coordinates'!$C$2))*COS(RADIANS(INDEX('ZIP Coordinates'!$C:$C,MATCH($B28,'ZIP Coordinates'!$A:$A,0))))*COS(RADIANS(INDEX('ZIP Coordinates'!$D:$D,MATCH($B28,'ZIP Coordinates'!$A:$A,0))-'ZIP Coordinates'!$D$2))))),"N/A") -> 128.9065 | E28: Ships to more than one ZIP in the source report (46514, (Unspecified / Consolidated)). ZIP shown is the one with the largest volume for this customer; distance is based on that ZIP only.
A29: 750092 | B29: 43517 | C29: =SUMIF('Raw Data'!$D$2:$D$878,$A29,'Raw Data'!$I$2:$I$878) -> 1351 | D29: =IFERROR(3958.8*ACOS(MIN(1,MAX(-1,SIN(RADIANS('ZIP Coordinates'!$C$2))*SIN(RADIANS(INDEX('ZIP Coordinates'!$C:$C,MATCH($B29,'ZIP Coordinates'!$A:$A,0))))+COS(RADIANS('ZIP Coordinates'!$C$2))*COS(RADIANS(INDEX('ZIP Coordinates'!$C:$C,MATCH($B29,'ZIP Coordinates'!$A:$A,0))))*COS(RADIANS(INDEX('ZIP Coordinates'!$D:$D,MATCH($B29,'ZIP Coordinates'!$A:$A,0))-'ZIP Coordinates'!$D$2))))),"N/A") -> 167.45112
A30: 1266 | B30: 46550 | C30: =SUMIF('Raw Data'!$D$2:$D$878,$A30,'Raw Data'!$I$2:$I$878) -> 556 | D30: =IFERROR(3958.8*ACOS(MIN(1,MAX(-1,SIN(RADIANS('ZIP Coordinates'!$C$2))*SIN(RADIANS(INDEX('ZIP Coordinates'!$C:$C,MATCH($B30,'ZIP Coordinates'!$A:$A,0))))+COS(RADIANS('ZIP Coordinates'!$C$2))*COS(RADIANS(INDEX('ZIP Coordinates'!$C:$C,MATCH($B30,'ZIP Coordinates'!$A:$A,0))))*COS(RADIANS(INDEX('ZIP Coordinates'!$D:$D,MATCH($B30,'ZIP Coordinates'!$A:$A,0))-'ZIP Coordinates'!$D$2))))),"N/A") -> 146.62233
A31: 0200 | B31: 49242 | C31: =SUMIF('Raw Data'!$D$2:$D$878,$A31,'Raw Data'!$I$2:$I$878) -> 378 | D31: =IFERROR(3958.8*ACOS(MIN(1,MAX(-1,SIN(RADIANS('ZIP Coordinates'!$C$2))*SIN(RADIANS(INDEX('ZIP Coordinates'!$C:$C,MATCH($B31,'ZIP Coordinates'!$A:$A,0))))+COS(RADIANS('ZIP Coordinates'!$C$2))*COS(RADIANS(INDEX('ZIP Coordinates'!$C:$C,MATCH($B31,'ZIP Coordinates'!$A:$A,0))))*COS(RADIANS(INDEX('ZIP Coordinates'!$D:$D,MATCH($B31,'ZIP Coordinates'!$A:$A,0))-'ZIP Coordinates'!$D$2))))),"N/A") -> 142.69042
A32: 729841 | B32: 43512 | C32: =SUMIF('Raw Data'!$D$2:$D$878,$A32,'Raw Data'!$I$2:$I$878) -> 1460 | D32: =IFERROR(3958.8*ACOS(MIN(1,MAX(-1,SIN(RADIANS('ZIP Coordinates'!$C$2))*SIN(RADIANS(INDEX('ZIP Coordinates'!$C:$C,MATCH($B32,'ZIP Coordinates'!$A:$A,0))))+COS(RADIANS('ZIP Coordinates'!$C$2))*COS(RADIANS(INDEX('ZIP Coordinates'!$C:$C,MATCH($B32,'ZIP Coordinates'!$A:$A,0))))*COS(RADIANS(INDEX('ZIP Coordinates'!$D:$D,MATCH($B32,'ZIP Coordinates'!$A:$A,0))-'ZIP Coordinates'!$D$2))))),"N/A") -> 186.92635
A33: 1580 | B33: 46743 | C33: =SUMIF('Raw Data'!$D$2:$D$878,$A33,'Raw Data'!$I$2:$I$878) -> 886 | D33: =IFERROR(3958.8*ACOS(MIN(1,MAX(-1,SIN(RADIANS('ZIP Coordinates'!$C$2))*SIN(RADIANS(INDEX('ZIP Coordinates'!$C:$C,MATCH($B33,'ZIP Coordinates'!$A:$A,0))))+COS(RADIANS('ZIP Coordinates'!$C$2))*COS(RADIANS(INDEX('ZIP Coordinates'!$C:$C,MATCH($B33,'ZIP Coordinates'!$A:$A,0))))*COS(RADIANS(INDEX('ZIP Coordinates'!$D:$D,MATCH($B33,'ZIP Coordinates'!$A:$A,0))-'ZIP Coordinates'!$D$2))))),"N/A") -> 178.20659
A34: 2738 | B34: 43502 | C34: =SUMIF('Raw Data'!$D$2:$D$878,$A34,'Raw Data'!$I$2:$I$878) -> 1077 | D34: =IFERROR(3958.8*ACOS(MIN(1,MAX(-1,SIN(RADIANS('ZIP Coordinates'!$C$2))*SIN(RADIANS(INDEX('ZIP Coordinates'!$C:$C,MATCH($B34,'ZIP Coordinates'!$A:$A,0))))+COS(RADIANS('ZIP Coordinates'!$C$2))*COS(RADIANS(INDEX('ZIP Coordinates'!$C:$C,MATCH($B34,'ZIP Coordinates'!$A:$A,0))))*COS(RADIANS(INDEX('ZIP Coordinates'!$D:$D,MATCH($B34,'ZIP Coordinates'!$A:$A,0))-'ZIP Coordinates'!$D$2))))),"N/A") -> 174.08007
A35: 1630 | B35: 49232 | C35: =SUMIF('Raw Data'!$D$2:$D$878,$A35,'Raw Data'!$I$2:$I$878) -> 1007 | D35: =IFERROR(3958.8*ACOS(MIN(1,MAX(-1,SIN(RADIANS('ZIP Coordinates'!$C$2))*SIN(RADIANS(INDEX('ZIP Coordinates'!$C:$C,MATCH($B35,'ZIP Coordinates'!$A:$A,0))))+COS(RADIANS('ZIP Coordinates'!$C$2))*COS(RADIANS(INDEX('ZIP Coordinates'!$C:$C,MATCH($B35,'ZIP Coordinates'!$A:$A,0))))*COS(RADIANS(INDEX('ZIP Coordinates'!$D:$D,MATCH($B35,'ZIP Coordinates'!$A:$A,0))-'ZIP Coordinates'!$D$2))))),"N/A") -> 150.27844
A36: 2668 | B36: 46787 | C36: =SUMIF('Raw Data'!$D$2:$D$878,$A36,'Raw Data'!$I$2:$I$878) -> 286 | D36: =IFERROR(3958.8*ACOS(MIN(1,MAX(-1,SIN(RADIANS('ZIP Coordinates'!$C$2))*SIN(RADIANS(INDEX('ZIP Coordinates'!$C:$C,MATCH($B36,'ZIP Coordinates'!$A:$A,0))))+COS(RADIANS('ZIP Coordinates'!$C$2))*COS(RADIANS(INDEX('ZIP Coordinates'!$C:$C,MATCH($B36,'ZIP Coordinates'!$A:$A,0))))*COS(RADIANS(INDEX('ZIP Coordinates'!$D:$D,MATCH($B36,'ZIP Coordinates'!$A:$A,0))-'ZIP Coordinates'!$D$2))))),"N/A") -> 175.57137
A37: 739023 | B37: 43532 | C37: =SUMIF('Raw Data'!$D$2:$D$878,$A37,'Raw Data'!$I$2:$I$878) -> 277 | D37: =IFERROR(3958.8*ACOS(MIN(1,MAX(-1,SIN(RADIANS('ZIP Coordinates'!$C$2))*SIN(RADIANS(INDEX('ZIP Coordinates'!$C:$C,MATCH($B37,'ZIP Coordinates'!$A:$A,0))))+COS(RADIANS('ZIP Coordinates'!$C$2))*COS(RADIANS(INDEX('ZIP Coordinates'!$C:$C,MATCH($B37,'ZIP Coordinates'!$A:$A,0))))*COS(RADIANS(INDEX('ZIP Coordinates'!$D:$D,MATCH($B37,'ZIP Coordinates'!$A:$A,0))-'ZIP Coordinates'!$D$2))))),"N/A") -> 188.59799
A38: 2366 | B38: 49255 | C38: =SUMIF('Raw Data'!$D$2:$D$878,$A38,'Raw Data'!$I$2:$I$878) -> 897 | D38: =IFERROR(3958.8*ACOS(MIN(1,MAX(-1,SIN(RADIANS('ZIP Coordinates'!$C$2))*SIN(RADIANS(INDEX('ZIP Coordinates'!$C:$C,MATCH($B38,'ZIP Coordinates'!$A:$A,0))))+COS(RADIANS('ZIP Coordinates'!$C$2))*COS(RADIANS(INDEX('ZIP Coordinates'!$C:$C,MATCH($B38,'ZIP Coordinates'!$A:$A,0))))*COS(RADIANS(INDEX('ZIP Coordinates'!$D:$D,MATCH($B38,'ZIP Coordinates'!$A:$A,0))-'ZIP Coordinates'!$D$2))))),"N/A") -> 143.5355
A39: 750074 | B39: 43533 | C39: =SUMIF('Raw Data'!$D$2:$D$878,$A39,'Raw Data'!$I$2:$I$878) -> 285 | D39: =IFERROR(3958.8*ACOS(MIN(1,MAX(-1,SIN(RADIANS('ZIP Coordinates'!$C$2))*SIN(RADIANS(INDEX('ZIP Coordinates'!$C:$C,MATCH($B39,'ZIP Coordinates'!$A:$A,0))))+COS(RADIANS('ZIP Coordinates'!$C$2))*COS(RADIANS(INDEX('ZIP Coordinates'!$C:$C,MATCH($B39,'ZIP Coordinates'!$A:$A,0))))*COS(RADIANS(INDEX('ZIP Coordinates'!$D:$D,MATCH($B39,'ZIP Coordinates'!$A:$A,0))-'ZIP Coordinates'!$D$2))))),"N/A") -> 173.39844
A40: 1696 | B40: 43545 | C40: =SUMIF('Raw Data'!$D$2:$D$878,$A40,'Raw Data'!$I$2:$I$878) -> 2756 | D40: =IFERROR(3958.8*ACOS(MIN(1,MAX(-1,SIN(RADIANS('ZIP Coordinates'!$C$2))*SIN(RADIANS(INDEX('ZIP Coordinates'!$C:$C,MATCH($B40,'ZIP Coordinates'!$A:$A,0))))+COS(RADIANS('ZIP Coordinates'!$C$2))*COS(RADIANS(INDEX('ZIP Coordinates'!$C:$C,MATCH($B40,'ZIP Coordinates'!$A:$A,0))))*COS(RADIANS(INDEX('ZIP Coordinates'!$D:$D,MATCH($B40,'ZIP Coordinates'!$A:$A,0))-'ZIP Coordinates'!$D$2))))),"N/A") -> 186.95027
...

Sheet Distance Band Summary
A1: Distance Band | B1: Total Units Shipped | C1: Line Items | D1: % of Total Units
A2: 0-49 mi | B2: =SUMIF('Raw Data'!$G$2:$G$878,$A2,'Raw Data'!$I$2:$I$878) -> 0 | C2: =COUNTIF('Raw Data'!$G$2:$G$878,$A2) -> 0 | D2: =B2/$B$8 -> 0
A3: 50-99 mi | B3: =SUMIF('Raw Data'!$G$2:$G$878,$A3,'Raw Data'!$I$2:$I$878) -> 137 | C3: =COUNTIF('Raw Data'!$G$2:$G$878,$A3) -> 5 | D3: =B3/$B$8 -> 0.0007354599
A4: 100-149 mi | B4: =SUMIF('Raw Data'!$G$2:$G$878,$A4,'Raw Data'!$I$2:$I$878) -> 28050 | C4: =COUNTIF('Raw Data'!$G$2:$G$878,$A4) -> 188 | D4: =B4/$B$8 -> 0.15058139
A5: 150-199 mi | B5: =SUMIF('Raw Data'!$G$2:$G$878,$A5,'Raw Data'!$I$2:$I$878) -> 154518 | C5: =COUNTIF('Raw Data'!$G$2:$G$878,$A5) -> 537 | D5: =B5/$B$8 -> 0.82950214
A6: 200+ mi | B6: =SUMIF('Raw Data'!$G$2:$G$878,$A6,'Raw Data'!$I$2:$I$878) -> 821 | C6: =COUNTIF('Raw Data'!$G$2:$G$878,$A6) -> 34 | D6: =B6/$B$8 -> 0.0044073911
A7: Unknown | B7: =SUMIF('Raw Data'!$G$2:$G$878,$A7,'Raw Data'!$I$2:$I$878) -> 2752 | C7: =COUNTIF('Raw Data'!$G$2:$G$878,$A7) -> 113 | D7: =B7/$B$8 -> 0.014773618
A8: GRAND TOTAL | B8: =SUM(B2:B7) -> 186278 | C8: =SUM(C2:C7) -> 877
A10: Note: each shipment line is bucketed by the straight-line distance between Country Dairy (49446) and that line's destination ZIP centroid. 'Unknown' covers lines with no ZIP on file or a ZIP not found in the centroid database (see 'ZIP Coordinates' tab).

Sheet Consolidated by ZIP
A1: ZIP Code | B1: Item Number | C1: Description | D1: Ship To Number | E1: Total Units Shipped | F1: Distance from Country Dairy (mi, straight-line)
A2: (Unspecified / Consolidated) | B2: 6005P | C2: Whole Milk Gallon | D2: 0251 | E2: =SUMIFS('Raw Data'!$I$2:$I$878,'Raw Data'!$A$2:$A$878,$A2,'Raw Data'!$B$2:$B$878,$B2,'Raw Data'!$D$2:$D$878,$D2) -> 35 | F2: =IFERROR(3958.8*ACOS(MIN(1,MAX(-1,SIN(RADIANS('ZIP Coordinates'!$C$2))*SIN(RADIANS(INDEX('ZIP Coordinates'!$C:$C,MATCH($A2,'ZIP Coordinates'!$A:$A,0))))+COS(RADIANS('ZIP Coordinates'!$C$2))*COS(RADIANS(INDEX('ZIP Coordinates'!$C:$C,MATCH($A2,'ZIP Coordinates'!$A:$A,0))))*COS(RADIANS(INDEX('ZIP Coordinates'!$D:$D,MATCH($A2,'ZIP Coordinates'!$A:$A,0))-'ZIP Coordinates'!$D$2))))),"N/A") -> N/A
A3: (Unspecified / Consolidated) | B3: 6013P | C3: Whole Milk - HALF GALLON | D3: 1486 | E3: =SUMIFS('Raw Data'!$I$2:$I$878,'Raw Data'!$A$2:$A$878,$A3,'Raw Data'!$B$2:$B$878,$B3,'Raw Data'!$D$2:$D$878,$D3) -> 4 | F3: =IFERROR(3958.8*ACOS(MIN(1,MAX(-1,SIN(RADIANS('ZIP Coordinates'!$C$2))*SIN(RADIANS(INDEX('ZIP Coordinates'!$C:$C,MATCH($A3,'ZIP Coordinates'!$A:$A,0))))+COS(RADIANS('ZIP Coordinates'!$C$2))*COS(RADIANS(INDEX('ZIP Coordinates'!$C:$C,MATCH($A3,'ZIP Coordinates'!$A:$A,0))))*COS(RADIANS(INDEX('ZIP Coordinates'!$D:$D,MATCH($A3,'ZIP Coordinates'!$A:$A,0))-'ZIP Coordinates'!$D$2))))),"N/A") -> N/A
A4: (Unspecified / Consolidated) | B4: 6014P | C4: 2% Milk - HALF GALLON | D4: 0251 | E4: =SUMIFS('Raw Data'!$I$2:$I$878,'Raw Data'!$A$2:$A$878,$A4,'Raw Data'!$B$2:$B$878,$B4,'Raw Data'!$D$2:$D$878,$D4) -> 32 | F4: =IFERROR(3958.8*ACOS(MIN(1,MAX(-1,SIN(RADIANS('ZIP Coordinates'!$C$2))*SIN(RADIANS(INDEX('ZIP Coordinates'!$C:$C,MATCH($A4,'ZIP Coordinates'!$A:$A,0))))+COS(RADIANS('ZIP Coordinates'!$C$2))*COS(RADIANS(INDEX('ZIP Coordinates'!$C:$C,MATCH($A4,'ZIP Coordinates'!$A:$A,0))))*COS(RADIANS(INDEX('ZIP Coordinates'!$D:$D,MATCH($A4,'ZIP Coordinates'!$A:$A,0))-'ZIP Coordinates'!$D$2))))),"N/A") -> N/A
A5: (Unspecified / Consolidated) | B5: 6044 | C5: Whole Milk Pint | D5: 2200 | E5: =SUMIFS('Raw Data'!$I$2:$I$878,'Raw Data'!$A$2:$A$878,$A5,'Raw Data'!$B$2:$B$878,$B5,'Raw Data'!$D$2:$D$878,$D5) -> 20 | F5: =IFERROR(3958.8*ACOS(MIN(1,MAX(-1,SIN(RADIANS('ZIP Coordinates'!$C$2))*SIN(RADIANS(INDEX('ZIP Coordinates'!$C:$C,MATCH($A5,'ZIP Coordinates'!$A:$A,0))))+COS(RADIANS('ZIP Coordinates'!$C$2))*COS(RADIANS(INDEX('ZIP Coordinates'!$C:$C,MATCH($A5,'ZIP Coordinates'!$A:$A,0))))*COS(RADIANS(INDEX('ZIP Coordinates'!$D:$D,MATCH($A5,'ZIP Coordinates'!$A:$A,0))-'ZIP Coordinates'!$D$2))))),"N/A") -> N/A
A6: (Unspecified / Consolidated) | B6: 6044 | C6: Whole Milk Pint | D6: 2834 | E6: =SUMIFS('Raw Data'!$I$2:$I$878,'Raw Data'!$A$2:$A$878,$A6,'Raw Data'!$B$2:$B$878,$B6,'Raw Data'!$D$2:$D$878,$D6) -> 40 | F6: =IFERROR(3958.8*ACOS(MIN(1,MAX(-1,SIN(RADIANS('ZIP Coordinates'!$C$2))*SIN(RADIANS(INDEX('ZIP Coordinates'!$C:$C,MATCH($A6,'ZIP Coordinates'!$A:$A,0))))+COS(RADIANS('ZIP Coordinates'!$C$2))*COS(RADIANS(INDEX('ZIP Coordinates'!$C:$C,MATCH($A6,'ZIP Coordinates'!$A:$A,0))))*COS(RADIANS(INDEX('ZIP Coordinates'!$D:$D,MATCH($A6,'ZIP Coordinates'!$A:$A,0))-'ZIP Coordinates'!$D$2))))),"N/A") -> N/A
A7: (Unspecified / Consolidated) | B7: 6044P | C7: Whole Milk Pint | D7: 1486 | E7: =SUMIFS('Raw Data'!$I$2:$I$878,'Raw Data'!$A$2:$A$878,$A7,'Raw Data'!$B$2:$B$878,$B7,'Raw Data'!$D$2:$D$878,$D7) -> 7 | F7: =IFERROR(3958.8*ACOS(MIN(1,MAX(-1,SIN(RADIANS('ZIP Coordinates'!$C$2))*SIN(RADIANS(INDEX('ZIP Coordinates'!$C:$C,MATCH($A7,'ZIP Coordinates'!$A:$A,0))))+COS(RADIANS('ZIP Coordinates'!$C$2))*COS(RADIANS(INDEX('ZIP Coordinates'!$C:$C,MATCH($A7,'ZIP Coordinates'!$A:$A,0))))*COS(RADIANS(INDEX('ZIP Coordinates'!$D:$D,MATCH($A7,'ZIP Coordinates'!$A:$A,0))-'ZIP Coordinates'!$D$2))))),"N/A") -> N/A
A8: (Unspecified / Consolidated) | B8: 6045 | C8: 2% Reduced Fat Milk Pint | D8: 1270 | E8: =SUMIFS('Raw Data'!$I$2:$I$878,'Raw Data'!$A$2:$A$878,$A8,'Raw Data'!$B$2:$B$878,$B8,'Raw Data'!$D$2:$D$878,$D8) -> 20 | F8: =IFERROR(3958.8*ACOS(MIN(1,MAX(-1,SIN(RADIANS('ZIP Coordinates'!$C$2))*SIN(RADIANS(INDEX('ZIP Coordinates'!$C:$C,MATCH($A8,'ZIP Coordinates'!$A:$A,0))))+COS(RADIANS('ZIP Coordinates'!$C$2))*COS(RADIANS(INDEX('ZIP Coordinates'!$C:$C,MATCH($A8,'ZIP Coordinates'!$A:$A,0))))*COS(RADIANS(INDEX('ZIP Coordinates'!$D:$D,MATCH($A8,'ZIP Coordinates'!$A:$A,0))-'ZIP Coordinates'!$D$2))))),"N/A") -> N/A
A9: (Unspecified / Consolidated) | B9: 6045P | C9: 2% Reduced Fat Milk Pint | D9: 0999 | E9: =SUMIFS('Raw Data'!$I$2:$I$878,'Raw Data'!$A$2:$A$878,$A9,'Raw Data'!$B$2:$B$878,$B9,'Raw Data'!$D$2:$D$878,$D9) -> 246 | F9: =IFERROR(3958.8*ACOS(MIN(1,MAX(-1,SIN(RADIANS('ZIP Coordinates'!$C$2))*SIN(RADIANS(INDEX('ZIP Coordinates'!$C:$C,MATCH($A9,'ZIP Coordinates'!$A:$A,0))))+COS(RADIANS('ZIP Coordinates'!$C$2))*COS(RADIANS(INDEX('ZIP Coordinates'!$C:$C,MATCH($A9,'ZIP Coordinates'!$A:$A,0))))*COS(RADIANS(INDEX('ZIP Coordinates'!$D:$D,MATCH($A9,'ZIP Coordinates'!$A:$A,0))-'ZIP Coordinates'!$D$2))))),"N/A") -> N/A
A10: (Unspecified / Consolidated) | B10: 6045P | C10: 2% Reduced Fat Milk Pint | D10: 1486 | E10: =SUMIFS('Raw Data'!$I$2:$I$878,'Raw Data'!$A$2:$A$878,$A10,'Raw Data'!$B$2:$B$878,$B10,'Raw Data'!$D$2:$D$878,$D10) -> 7 | F10: =IFERROR(3958.8*ACOS(MIN(1,MAX(-1,SIN(RADIANS('ZIP Coordinates'!$C$2))*SIN(RADIANS(INDEX('ZIP Coordinates'!$C:$C,MATCH($A10,'ZIP Coordinates'!$A:$A,0))))+COS(RADIANS('ZIP Coordinates'!$C$2))*COS(RADIANS(INDEX('ZIP Coordinates'!$C:$C,MATCH($A10,'ZIP Coordinates'!$A:$A,0))))*COS(RADIANS(INDEX('ZIP Coordinates'!$D:$D,MATCH($A10,'ZIP Coordinates'!$A:$A,0))-'ZIP Coordinates'!$D$2))))),"N/A") -> N/A
A11: (Unspecified / Consolidated) | B11: 6049P | C11: Strawberry Whole Milk Pint | D11: 1270 | E11: =SUMIFS('Raw Data'!$I$2:$I$878,'Raw Data'!$A$2:$A$878,$A11,'Raw Data'!$B$2:$B$878,$B11,'Raw Data'!$D$2:$D$878,$D11) -> 10 | F11: =IFERROR(3958.8*ACOS(MIN(1,MAX(-1,SIN(RADIANS('ZIP Coordinates'!$C$2))*SIN(RADIANS(INDEX('ZIP Coordinates'!$C:$C,MATCH($A11,'ZIP Coordinates'!$A:$A,0))))+COS(RADIANS('ZIP Coordinates'!$C$2))*COS(RADIANS(INDEX('ZIP Coordinates'!$C:$C,MATCH($A11,'ZIP Coordinates'!$A:$A,0))))*COS(RADIANS(INDEX('ZIP Coordinates'!$D:$D,MATCH($A11,'ZIP Coordinates'!$A:$A,0))-'ZIP Coordinates'!$D$2))))),"N/A") -> N/A
A12: (Unspecified / Consolidated) | B12: 6049P | C12: Strawberry Whole Milk Pint | D12: 1486 | E12: =SUMIFS('Raw Data'!$I$2:$I$878,'Raw Data'!$A$2:$A$878,$A12,'Raw Data'!$B$2:$B$878,$B12,'Raw Data'!$D$2:$D$878,$D12) -> 6 | F12: =IFERROR(3958.8*ACOS(MIN(1,MAX(-1,SIN(RADIANS('ZIP Coordinates'!$C$2))*SIN(RADIANS(INDEX('ZIP Coordinates'!$C:$C,MATCH($A12,'ZIP Coordinates'!$A:$A,0))))+COS(RADIANS('ZIP Coordinates'!$C$2))*COS(RADIANS(INDEX('ZIP Coordinates'!$C:$C,MATCH($A12,'ZIP Coordinates'!$A:$A,0))))*COS(RADIANS(INDEX('ZIP Coordinates'!$D:$D,MATCH($A12,'ZIP Coordinates'!$A:$A,0))-'ZIP Coordinates'!$D$2))))),"N/A") -> N/A
A13: (Unspecified / Consolidated) | B13: 6049P | C13: Strawberry Whole Milk Pint | D13: 2200 | E13: =SUMIFS('Raw Data'!$I$2:$I$878,'Raw Data'!$A$2:$A$878,$A13,'Raw Data'!$B$2:$B$878,$B13,'Raw Data'!$D$2:$D$878,$D13) -> 20 | F13: =IFERROR(3958.8*ACOS(MIN(1,MAX(-1,SIN(RADIANS('ZIP Coordinates'!$C$2))*SIN(RADIANS(INDEX('ZIP Coordinates'!$C:$C,MATCH($A13,'ZIP Coordinates'!$A:$A,0))))+COS(RADIANS('ZIP Coordinates'!$C$2))*COS(RADIANS(INDEX('ZIP Coordinates'!$C:$C,MATCH($A13,'ZIP Coordinates'!$A:$A,0))))*COS(RADIANS(INDEX('ZIP Coordinates'!$D:$D,MATCH($A13,'ZIP Coordinates'!$A:$A,0))-'ZIP Coordinates'!$D$2))))),"N/A") -> N/A
... A646: 68138 | B646: 7676 | C646: Village Pie Butter | D646: 2792 | E646: =SUMIFS('Raw Data'!$I$2:$I$878,'Raw Data'!$A$2:$A$878,$A646,'Raw Data'!$B$2:$B$878,$B646,'Raw Data'!$D$2:$D$878,$D646) -> 20 | F646: =IFERROR(3958.8*ACOS(MIN(1,MAX(-1,SIN(RADIANS('ZIP Coordinates'!$C$2))*SIN(RADIANS(INDEX('ZIP Coordinates'!$C:$C,MATCH($A646,'ZIP Coordinates'!$A:$A,0))))+COS(RADIANS('ZIP Coordinates'!$C$2))*COS(RADIANS(INDEX('ZIP Coordinates'!$C:$C,MATCH($A646,'ZIP Coordinates'!$A:$A,0))))*COS(RADIANS(INDEX('ZIP Coordinates'!$D:$D,MATCH($A646,'ZIP Coordinates'!$A:$A,0))-'ZIP Coordinates'!$D$2))))),"N/A") -> 526.42489

Sheet Raw Data
A1: ZIP Code | B1: Item Number | C1: Description | D1: Ship To Number | E1: Quantity Shipped | F1: Distance from Country Dairy (mi, straight-line) | G1: Distance Band | H1: Units per Case Applied | I1: Total Units Shipped
A2: (Unspecified / Consolidated) | B2: 6005P | C2: Whole Milk Gallon | D2: 0251 | E2: 1 | F2: =IFERROR(3958.8*ACOS(MIN(1,MAX(-1,SIN(RADIANS('ZIP Coordinates'!$C$2))*SIN(RADIANS(INDEX('ZIP Coordinates'!$C:$C,MATCH($A2,'ZIP Coordinates'!$A:$A,0))))+COS(RADIANS('ZIP Coordinates'!$C$2))*COS(RADIANS(INDEX('ZIP Coordinates'!$C:$C,MATCH($A2,'ZIP Coordinates'!$A:$A,0))))*COS(RADIANS(INDEX('ZIP Coordinates'!$D:$D,MATCH($A2,'ZIP Coordinates'!$A:$A,0))-'ZIP Coordinates'!$D$2))))),"N/A") -> N/A | G2: =IF($F2="N/A","Unknown",IF($F2<50,"0-49 mi",IF($F2<100,"50-99 mi",IF($F2<150,"100-149 mi",IF($F2<200,"150-199 mi","200+ mi"))))) -> Unknown | H2: =IF(RIGHT($B2,1)="P",1,IF(ISNUMBER(SEARCH("HALF GALLON",$C2)),Assumptions!$B$4,IF(ISNUMBER(SEARCH("GALLON",$C2)),Assumptions!$B$3,IF(ISNUMBER(SEARCH("QUART",$C2)),Assumptions!$B$5,IF(ISNUMBER(SEARCH("PINT",$C2)),Assumptions!$B$6,Assumptions!$B$7))))) -> 1 | I2: =$E2*$H2 -> 1
A3: (Unspecified / Consolidated) | B3: 6005P | C3: Whole Milk Gallon | D3: 0251 | E3: 1 | F3: =IFERROR(3958.8*ACOS(MIN(1,MAX(-1,SIN(RADIANS('ZIP Coordinates'!$C$2))*SIN(RADIANS(INDEX('ZIP Coordinates'!$C:$C,MATCH($A3,'ZIP Coordinates'!$A:$A,0))))+COS(RADIANS('ZIP Coordinates'!$C$2))*COS(RADIANS(INDEX('ZIP Coordinates'!$C:$C,MATCH($A3,'ZIP Coordinates'!$A:$A,0))))*COS(RADIANS(INDEX('ZIP Coordinates'!$D:$D,MATCH($A3,'ZIP Coordinates'!$A:$A,0))-'ZIP Coordinates'!$D$2))))),"N/A") -> N/A | G3: =IF($F3="N/A","Unknown",IF($F3<50,"0-49 mi",IF($F3<100,"50-99 mi",IF($F3<150,"100-149 mi",IF($F3<200,"150-199 mi","200+ mi"))))) -> Unknown | H3: =IF(RIGHT($B3,1)="P",1,IF(ISNUMBER(SEARCH("HALF GALLON",$C3)),Assumptions!$B$4,IF(ISNUMBER(SEARCH("GALLON",$C3)),Assumptions!$B$3,IF(ISNUMBER(SEARCH("QUART",$C3)),Assumptions!$B$5,IF(ISNUMBER(SEARCH("PINT",$C3)),Assumptions!$B$6,Assumptions!$B$7))))) -> 1 | I3: =$E3*$H3 -> 1
A4: (Unspecified / Consolidated) | B4: 6005P | C4: Whole Milk Gallon | D4: 0251 | E4: 3 | F4: =IFERROR(3958.8*ACOS(MIN(1,MAX(-1,SIN(RADIANS('ZIP Coordinates'!$C$2))*SIN(RADIANS(INDEX('ZIP Coordinates'!$C:$C,MATCH($A4,'ZIP Coordinates'!$A:$A,0))))+COS(RADIANS('ZIP Coordinates'!$C$2))*COS(RADIANS(INDEX('ZIP Coordinates'!$C:$C,MATCH($A4,'ZIP Coordinates'!$A:$A,0))))*COS(RADIANS(INDEX('ZIP Coordinates'!$D:$D,MATCH($A4,'ZIP Coordinates'!$A:$A,0))-'ZIP Coordinates'!$D$2))))),"N/A") -> N/A | G4: =IF($F4="N/A","Unknown",IF($F4<50,"0-49 mi",IF($F4<100,"50-99 mi",IF($F4<150,"100-149 mi",IF($F4<200,"150-199 mi","200+ mi"))))) -> Unknown | H4: =IF(RIGHT($B4,1)="P",1,IF(ISNUMBER(SEARCH("HALF GALLON",$C4)),Assumptions!$B$4,IF(ISNUMBER(SEARCH("GALLON",$C4)),Assumptions!$B$3,IF(ISNUMBER(SEARCH("QUART",$C4)),Assumptions!$B$5,IF(ISNUMBER(SEARCH("PINT",$C4)),Assumptions!$B$6,Assumptions!$B$7))))) -> 1 | I4: =$E4*$H4 -> 3
A5: (Unspecified / Consolidated) | B5: 6005P | C5: Whole Milk Gallon | D5: 0251 | E5: 3 | F5: =IFERROR(3958.8*ACOS(MIN(1,MAX(-1,SIN(RADIANS('ZIP Coordinates'!$C$2))*SIN(RADIANS(INDEX('ZIP Coordinates'!$C:$C,MATCH($A5,'ZIP Coordinates'!$A:$A,0))))+COS(RADIANS('ZIP Coordinates'!$C$2))*COS(RADIANS(INDEX('ZIP Coordinates'!$C:$C,MATCH($A5,'ZIP Coordinates'!$A:$A,0))))*COS(RADIANS(INDEX('ZIP Coordinates'!$D:$D,MATCH($A5,'ZIP Coordinates'!$A:$A,0))-'ZIP Coordinates'!$D$2))))),"N/A") -> N/A | G5: =IF($F5="N/A","Unknown",IF($F5<50,"0-49 mi",IF($F5<100,"50-99 mi",IF($F5<150,"100-149 mi",IF($F5<200,"150-199 mi","200+ mi"))))) -> Unknown | H5: =IF(RIGHT($B5,1)="P",1,IF(ISNUMBER(SEARCH("HALF GALLON",$C5)),Assumptions!$B$4,IF(ISNUMBER(SEARCH("GALLON",$C5)),Assumptions!$B$3,IF(ISNUMBER(SEARCH("QUART",$C5)),Assumptions!$B$5,IF(ISNUMBER(SEARCH("PINT",$C5)),Assumptions!$B$6,Assumptions!$B$7))))) -> 1 | I5: =$E5*$H5 -> 3
A6: (Unspecified / Consolidated) | B6: 6005P | C6: Whole Milk Gallon | D6: 0251 | E6: 1 | F6: =IFERROR(3958.8*ACOS(MIN(1,MAX(-1,SIN(RADIANS('ZIP Coordinates'!$C$2))*SIN(RADIANS(INDEX('ZIP Coordinates'!$C:$C,MATCH($A6,'ZIP Coordinates'!$A:$A,0))))+COS(RADIANS('ZIP Coordinates'!$C$2))*COS(RADIANS(INDEX('ZIP Coordinates'!$C:$C,MATCH($A6,'ZIP Coordinates'!$A:$A,0))))*COS(RADIANS(INDEX('ZIP Coordinates'!$D:$D,MATCH($A6,'ZIP Coordinates'!$A:$A,0))-'ZIP Coordinates'!$D$2))))),"N/A") -> N/A | G6: =IF($F6="N/A","Unknown",IF($F6<50,"0-49 mi",IF($F6<100,"50-99 mi",IF($F6<150,"100-149 mi",IF($F6<200,"150-199 mi","200+ mi"))))) -> Unknown | H6: =IF(RIGHT($B6,1)="P",1,IF(ISNUMBER(SEARCH("HALF GALLON",$C6)),Assumptions!$B$4,IF(ISNUMBER(SEARCH("GALLON",$C6)),Assumptions!$B$3,IF(ISNUMBER(SEARCH("QUART",$C6)),Assumptions!$B$5,IF(ISNUMBER(SEARCH("PINT",$C6)),Assumptions!$B$6,Assumptions!$B$7))))) -> 1 | I6: =$E6*$H6 -> 1
A7: (Unspecified / Consolidated) | B7: 6005P | C7: Whole Milk Gallon | D7: 0251 | E7: 3 | F7: =IFERROR(3958.8*ACOS(MIN(1,MAX(-1,SIN(RADIANS('ZIP Coordinates'!$C$2))*SIN(RADIANS(INDEX('ZIP Coordinates'!$C:$C,MATCH($A7,'ZIP Coordinates'!$A:$A,0))))+COS(RADIANS('ZIP Coordinates'!$C$2))*COS(RADIANS(INDEX('ZIP Coordinates'!$C:$C,MATCH($A7,'ZIP Coordinates'!$A:$A,0))))*COS(RADIANS(INDEX('ZIP Coordinates'!$D:$D,MATCH($A7,'ZIP Coordinates'!$A:$A,0))-'ZIP Coordinates'!$D$2))))),"N/A") -> N/A | G7: =IF($F7="N/A","Unknown",IF($F7<50,"0-49 mi",IF($F7<100,"50-99 mi",IF($F7<150,"100-149 mi",IF($F7<200,"150-199 mi","200+ mi"))))) -> Unknown | H7: =IF(RIGHT($B7,1)="P",1,IF(ISNUMBER(SEARCH("HALF GALLON",$C7)),Assumptions!$B$4,IF(ISNUMBER(SEARCH("GALLON",$C7)),Assumptions!$B$3,IF(ISNUMBER(SEARCH("QUART",$C7)),Assumptions!$B$5,IF(ISNUMBER(SEARCH("PINT",$C7)),Assumptions!$B$6,Assumptions!$B$7))))) -> 1 | I7: =$E7*$H7 -> 3
A8: (Unspecified / Consolidated) | B8: 6005P | C8: Whole Milk Gallon | D8: 0251 | E8: 1 | F8: =IFERROR(3958.8*ACOS(MIN(1,MAX(-1,SIN(RADIANS('ZIP Coordinates'!$C$2))*SIN(RADIANS(INDEX('ZIP Coordinates'!$C:$C,MATCH($A8,'ZIP Coordinates'!$A:$A,0))))+COS(RADIANS('ZIP Coordinates'!$C$2))*COS(RADIANS(INDEX('ZIP Coordinates'!$C:$C,MATCH($A8,'ZIP Coordinates'!$A:$A,0))))*COS(RADIANS(INDEX('ZIP Coordinates'!$D:$D,MATCH($A8,'ZIP Coordinates'!$A:$A,0))-'ZIP Coordinates'!$D$2))))),"N/A") -> N/A | G8: =IF($F8="N/A","Unknown",IF($F8<50,"0-49 mi",IF($F8<100,"50-99 mi",IF($F8<150,"100-149 mi",IF($F8<200,"150-199 mi","200+ mi"))))) -> Unknown | H8: =IF(RIGHT($B8,1)="P",1,IF(ISNUMBER(SEARCH("HALF GALLON",$C8)),Assumptions!$B$4,IF(ISNUMBER(SEARCH("GALLON",$C8)),Assumptions!$B$3,IF(ISNUMBER(SEARCH("QUART",$C8)),Assumptions!$B$5,IF(ISNUMBER(SEARCH("PINT",$C8)),Assumptions!$B$6,Assumptions!$B$7))))) -> 1 | I8: =$E8*$H8 -> 1
A9: (Unspecified / Consolidated) | B9: 6005P | C9: Whole Milk Gallon | D9: 0251 | E9: 1 | F9: =IFERROR(3958.8*ACOS(MIN(1,MAX(-1,SIN(RADIANS('ZIP Coordinates'!$C$2))*SIN(RADIANS(INDEX('ZIP Coordinates'!$C:$C,MATCH($A9,'ZIP Coordinates'!$A:$A,0))))+COS(RADIANS('ZIP Coordinates'!$C$2))*COS(RADIANS(INDEX('ZIP Coordinates'!$C:$C,MATCH($A9,'ZIP Coordinates'!$A:$A,0))))*COS(RADIANS(INDEX('ZIP Coordinates'!$D:$D,MATCH($A9,'ZIP Coordinates'!$A:$A,0))-'ZIP Coordinates'!$D$2))))),"N/A") -> N/A | G9: =IF($F9="N/A","Unknown",IF($F9<50,"0-49 mi",IF($F9<100,"50-99 mi",IF($F9<150,"100-149 mi",IF($F9<200,"150-199 mi","200+ mi"))))) -> Unknown | H9: =IF(RIGHT($B9,1)="P",1,IF(ISNUMBER(SEARCH("HALF GALLON",$C9)),Assumptions!$B$4,IF(ISNUMBER(SEARCH("GALLON",$C9)),Assumptions!$B$3,IF(ISNUMBER(SEARCH("QUART",$C9)),Assumptions!$B$5,IF(ISNUMBER(SEARCH("PINT",$C9)),Assumptions!$B$6,Assumptions!$B$7))))) -> 1 | I9: =$E9*$H9 -> 1
A10: (Unspecified / Consolidated) | B10: 6005P | C10: Whole Milk Gallon | D10: 0251 | E10: 2 | F10: =IFERROR(3958.8*ACOS(MIN(1,MAX(-1,SIN(RADIANS('ZIP Coordinates'!$C$2))*SIN(RADIANS(INDEX('ZIP Coordinates'!$C:$C,MATCH($A10,'ZIP Coordinates'!$A:$A,0))))+COS(RADIANS('ZIP Coordinates'!$C$2))*COS(RADIANS(INDEX('ZIP Coordinates'!$C:$C,MATCH($A10,'ZIP Coordinates'!$A:$A,0))))*COS(RADIANS(INDEX('ZIP Coordinates'!$D:$D,MATCH($A10,'ZIP Coordinates'!$A:$A,0))-'ZIP Coordinates'!$D$2))))),"N/A") -> N/A | G10: =IF($F10="N/A","Unknown",IF($F10<50,"0-49 mi",IF($F10<100,"50-99 mi",IF($F10<150,"100-149 mi",IF($F10<200,"150-199 mi","200+ mi"))))) -> Unknown | H10: =IF(RIGHT($B10,1)="P",1,IF(ISNUMBER(SEARCH("HALF GALLON",$C10)),Assumptions!$B$4,IF(ISNUMBER(SEARCH("GALLON",$C10)),Assumptions!$B$3,IF(ISNUMBER(SEARCH("QUART",$C10)),Assumptions!$B$5,IF(ISNUMBER(SEARCH("PINT",$C10)),Assumptions!$B$6,Assumptions!$B$7))))) -> 1 | I10: =$E10*$H10 -> 2
A11: (Unspecified / Consolidated) | B11: 6005P | C11: Whole Milk Gallon | D11: 0251 | E11: 1 | F11: =IFERROR(3958.8*ACOS(MIN(1,MAX(-1,SIN(RADIANS('ZIP Coordinates'!$C$2))*SIN(RADIANS(INDEX('ZIP Coordinates'!$C:$C,MATCH($A11,'ZIP Coordinates'!$A:$A,0))))+COS(RADIANS('ZIP Coordinates'!$C$2))*COS(RADIANS(INDEX('ZIP Coordinates'!$C:$C,MATCH($A11,'ZIP Coordinates'!$A:$A,0))))*COS(RADIANS(INDEX('ZIP Coordinates'!$D:$D,MATCH($A11,'ZIP Coordinates'!$A:$A,0))-'ZIP Coordinates'!$D$2))))),"N/A") -> N/A | G11: =IF($F11="N/A","Unknown",IF($F11<50,"0-49 mi",IF($F11<100,"50-99 mi",IF($F11<150,"100-149 mi",IF($F11<200,"150-199 mi","200+ mi"))))) -> Unknown | H11: =IF(RIGHT($B11,1)="P",1,IF(ISNUMBER(SEARCH("HALF GALLON",$C11)),Assumptions!$B$4,IF(ISNUMBER(SEARCH("GALLON",$C11)),Assumptions!$B$3,IF(ISNUMBER(SEARCH("QUART",$C11)),Assumptions!$B$5,IF(ISNUMBER(SEARCH("PINT",$C11)),Assumptions!$B$6,Assumptions!$B$7))))) -> 1 | I11: =$E11*$H11 -> 1
A12: (Unspecified / Consolidated) | B12: 6005P | C12: Whole Milk Gallon | D12: 0251 | E12: 3 | F12: =IFERROR(3958.8*ACOS(MIN(1,MAX(-1,SIN(RADIANS('ZIP Coordinates'!$C$2))*SIN(RADIANS(INDEX('ZIP Coordinates'!$C:$C,MATCH($A12,'ZIP Coordinates'!$A:$A,0))))+COS(RADIANS('ZIP Coordinates'!$C$2))*COS(RADIANS(INDEX('ZIP Coordinates'!$C:$C,MATCH($A12,'ZIP Coordinates'!$A:$A,0))))*COS(RADIANS(INDEX('ZIP Coordinates'!$D:$D,MATCH($A12,'ZIP Coordinates'!$A:$A,0))-'ZIP Coordinates'!$D$2))))),"N/A") -> N/A | G12: =IF($F12="N/A","Unknown",IF($F12<50,"0-49 mi",IF($F12<100,"50-99 mi",IF($F12<150,"100-149 mi",IF($F12<200,"150-199 mi","200+ mi"))))) -> Unknown | H12: =IF(RIGHT($B12,1)="P",1,IF(ISNUMBER(SEARCH("HALF GALLON",$C12)),Assumptions!$B$4,IF(ISNUMBER(SEARCH("GALLON",$C12)),Assumptions!$B$3,IF(ISNUMBER(SEARCH("QUART",$C12)),Assumptions!$B$5,IF(ISNUMBER(SEARCH("PINT",$C12)),Assumptions!$B$6,Assumptions!$B$7))))) -> 1 | I12: =$E12*$H12 -> 3
